Workbook

Sheet 제안서
A1: 자산배분 제안서 | H1: =IFERROR(VALUE(LEFT($B$11,1)),3)
A2: 미래에셋증권 | H2: =IF($B$13<>"▶ 조회 실행","",$H$1&"|"&CHOOSE(MATCH($B$10,{"1년 이내","3년","5년","5년 초과"},0),1,3,5,10))
H3: =IF(SUM($I19:$I25)=0,"",SUMPRODUCT($I19:$I25,$G19:$G25)/SUM($I19:$I25))
H4: =IF(ISNUMBER($G25),$G25,0)
H5: =IF(OR($H$3="",$B$12="",$H$3<=$H$4),"",MEDIAN(0,($B$12-$H$4)/($H$3-$H$4),1))
A6: 1 | B6: 조회 조건
A8: 고객명
A9: 투자금액 (만원) | B9: 10000
A10: 투자기간 | B10: 5년 초과
A11: 위험성향 | B11: 3 위험중립형
A12: 목표 연수익률 (%)
A13: 조회 | B13: ▶ 조회 실행 | C13: ← 조건을 고친 뒤 이 칸에서 「▶ 조회 실행」을 고르십시오. 「… 조건 입력 중」로 두면 표가 비워집니다.
A16: 2 | B16: 제안 배분
A18: 자산군 | B18: 제안 비중 | C18: 조정 비중 | D18: 쓰는 비중 | E18: 금액(만원) | F18: 과거 1년(중앙) | G18: 기대수익률 (가정)
A19: 국내주식 | B19: =IFERROR(INDEX(배분규칙!$D$4:$J$23,MATCH($H$2,배분규칙!$A$4:$A$23,0),MATCH($A19,배분규칙!$D$3:$J$3,0)),"") | D19: =IF($C19="",IF(ISNUMBER($B19),$B19,0),$C19) | E19: =$B$9*$D19 | F19: =IFERROR(INDEX(자산군!$D$7:$D$13,MATCH($A19,자산군!$A$7:$A$13,0)),"—") | G19: 0.0781 | H19: =IF(ISNUMBER($F19),$F19,0) | I19: =IF(AND($A19<>"현금",ISNUMBER($G19)),5,0)
A20: 해외주식 | B20: =IFERROR(INDEX(배분규칙!$D$4:$J$23,MATCH($H$2,배분규칙!$A$4:$A$23,0),MATCH($A20,배분규칙!$D$3:$J$3,0)),"") | D20: =IF($C20="",IF(ISNUMBER($B20),$B20,0),$C20) | E20: =$B$9*$D20 | F20: =IFERROR(INDEX(자산군!$D$7:$D$13,MATCH($A20,자산군!$A$7:$A$13,0)),"—") | G20: 0.0781 | H20: =IF(ISNUMBER($F20),$F20,0) | I20: =IF(AND($A20<>"현금",ISNUMBER($G20)),10,0)
A21: 국내ETF | B21: =IFERROR(INDEX(배분규칙!$D$4:$J$23,MATCH($H$2,배분규칙!$A$4:$A$23,0),MATCH($A21,배분규칙!$D$3:$J$3,0)),"") | D21: =IF($C21="",IF(ISNUMBER($B21),$B21,0),$C21) | E21: =$B$9*$D21 | F21: =IFERROR(INDEX(자산군!$D$7:$D$13,MATCH($A21,자산군!$A$7:$A$13,0)),"—") | G21: 0.0553 | H21: =IF(ISNUMBER($F21),$F21,0) | I21: =IF(AND($A21<>"현금",ISNUMBER($G21)),15,0)
A22: 해외ETF | B22: =IFERROR(INDEX(배분규칙!$D$4:$J$23,MATCH($H$2,배분규칙!$A$4:$A$23,0),MATCH($A22,배분규칙!$D$3:$J$3,0)),"") | D22: =IF($C22="",IF(ISNUMBER($B22),$B22,0),$C22) | E22: =$B$9*$D22 | F22: =IFERROR(INDEX(자산군!$D$7:$D$13,MATCH($A22,자산군!$A$7:$A$13,0)),"—") | G22: 0.0561 | H22: =IF(ISNUMBER($F22),$F22,0) | I22: =IF(AND($A22<>"현금",ISNUMBER($G22)),15,0)
A23: 국내펀드 | B23: =IFERROR(INDEX(배분규칙!$D$4:$J$23,MATCH($H$2,배분규칙!$A$4:$A$23,0),MATCH($A23,배분규칙!$D$3:$J$3,0)),"") | D23: =IF($C23="",IF(ISNUMBER($B23),$B23,0),$C23) | E23: =$B$9*$D23 | F23: =IFERROR(INDEX(자산군!$D$7:$D$13,MATCH($A23,자산군!$A$7:$A$13,0)),"—") | G23: 0.0451 | H23: =IF(ISNUMBER($F23),$F23,0) | I23: =IF(AND($A23<>"현금",ISNUMBER($G23)),20,0)
A24: 해외펀드 | B24: =IFERROR(INDEX(배분규칙!$D$4:$J$23,MATCH($H$2,배분규칙!$A$4:$A$23,0),MATCH($A24,배분규칙!$D$3:$J$3,0)),"") | D24: =IF($C24="",IF(ISNUMBER($B24),$B24,0),$C24) | E24: =$B$9*$D24 | F24: =IFERROR(INDEX(자산군!$D$7:$D$13,MATCH($A24,자산군!$A$7:$A$13,0)),"—") | G24: 0.0561 | H24: =IF(ISNUMBER($F24),$F24,0) | I24: =IF(AND($A24<>"현금",ISNUMBER($G24)),20,0)
A25: 현금 | B25: =IFERROR(INDEX(배분규칙!$D$4:$J$23,MATCH($H$2,배분규칙!$A$4:$A$23,0),MATCH($A25,배분규칙!$D$3:$J$3,0)),"") | D25: =IF($C25="",IF(ISNUMBER($B25),$B25,0),$C25) | E25: =$B$9*$D25 | F25: =IFERROR(INDEX(자산군!$D$7:$D$13,MATCH($A25,자산군!$A$7:$A$13,0)),"—") | G25: 0.0281 | H25: =IF(ISNUMBER($F25),$F25,0) | I25: =IF(AND($A25<>"현금",ISNUMBER($G25)),15,0)
A26: 합계 | B26: =SUM($B19:$B25) | C26: =IF(COUNT($C19:$C25)=0,"—",SUM($C19:$C25)) | D26: =SUM($D19:$D25) | E26: =SUM($E19:$E25) | F26: =SUMPRODUCT($D19:$D25,$H19:$H25) | G26: =IF(COUNT($G19:$G25)=0,"가정 미입력",SUMPRODUCT($D19:$D25,$G19:$G25))
A27: 점검 | B27: =IF($H$2="","조회 조건에서 「▶ 조회 실행」을 고르시면 배분이 나옵니다",IF(ABS($D26-1)>0.0005,"비중 합계가 100% 가 아닙니다 — 조정 비중을 맞추십시오","비중 합계 100% 입니다")) | G27: =COUNT($G19:$G25)&" / 7 가정"
A30: 3 | B30: 제안 상품
A32: 「상품」 시트에서 채택을 Y 로 바꾸면 여기에 올라옵니다. 배분액은 그 자산군 금액을 채택한 수로 나눈 것입니다. 상품 아래 회색 줄이 고른 까닭입니다 — 왼쪽 여백의 「−」로 접으면 인쇄에서도 빠집니다.
A34: 자산군 | B34: 상품 | C34: 측정 | D34: 연평균 | E34: 변동성 | F34: 보수 | G34: 배분액(만원)
A35: 국내주식 | B35: =IFERROR(INDEX(상품!$C$7:$C$156,MATCH($A$35&"|"&1,상품!$N$7:$N$156,0)),"") | C35: =IFERROR(INDEX(상품!$G$7:$G$156,MATCH($A$35&"|"&1,상품!$N$7:$N$156,0)),"") | D35: =IFERROR(INDEX(상품!$I$7:$I$156,MATCH($A$35&"|"&1,상품!$N$7:$N$156,0)),"") | E35: =IFERROR(INDEX(상품!$J$7:$J$156,MATCH($A$35&"|"&1,상품!$N$7:$N$156,0)),"") | F35: =IFERROR(INDEX(상품!$L$7:$L$156,MATCH($A$35&"|"&1,상품!$N$7:$N$156,0)),"") | G35: =IFERROR(IF(INDEX(상품!$C$7:$C$156,MATCH($A$35&"|"&1,상품!$N$7:$N$156,0))="","",ROUND($E$19/COUNTIFS(상품!$A$7:$A$156,"Y",상품!$B$7:$B$156,$A35),0)),"")
A36: =IFERROR(INDEX(상품!$M$7:$M$156,MATCH($A$35&"|"&1,상품!$N$7:$N$156,0)),"") | S36: 근거
B37: =IFERROR(INDEX(상품!$C$7:$C$156,MATCH($A$35&"|"&2,상품!$N$7:$N$156,0)),"") | C37: =IFERROR(INDEX(상품!$G$7:$G$156,MATCH($A$35&"|"&2,상품!$N$7:$N$156,0)),"") | D37: =IFERROR(INDEX(상품!$I$7:$I$156,MATCH($A$35&"|"&2,상품!$N$7:$N$156,0)),"") | E37: =IFERROR(INDEX(상품!$J$7:$J$156,MATCH($A$35&"|"&2,상품!$N$7:$N$156,0)),"") | F37: =IFERROR(INDEX(상품!$L$7:$L$156,MATCH($A$35&"|"&2,상품!$N$7:$N$156,0)),"") | G37: =IFERROR(IF(INDEX(상품!$C$7:$C$156,MATCH($A$35&"|"&2,상품!$N$7:$N$156,0))="","",ROUND($E$19/COUNTIFS(상품!$A$7:$A$156,"Y",상품!$B$7:$B$156,$A35),0)),"")
A38: =IFERROR(INDEX(상품!$M$7:$M$156,MATCH($A$35&"|"&2,상품!$N$7:$N$156,0)),"") | S38: 근거
B39: =IFERROR(INDEX(상품!$C$7:$C$156,MATCH($A$35&"|"&3,상품!$N$7:$N$156,0)),"") | C39: =IFERROR(INDEX(상품!$G$7:$G$156,MATCH($A$35&"|"&3,상품!$N$7:$N$156,0)),"") | D39: =IFERROR(INDEX(상품!$I$7:$I$156,MATCH($A$35&"|"&3,상품!$N$7:$N$156,0)),"") | E39: =IFERROR(INDEX(상품!$J$7:$J$156,MATCH($A$35&"|"&3,상품!$N$7:$N$156,0)),"") | F39: =IFERROR(INDEX(상품!$L$7:$L$156,MATCH($A$35&"|"&3,상품!$N$7:$N$156,0)),"") | G39: =IFERROR(IF(INDEX(상품!$C$7:$C$156,MATCH($A$35&"|"&3,상품!$N$7:$N$156,0))="","",ROUND($E$19/COUNTIFS(상품!$A$7:$A$156,"Y",상품!$B$7:$B$156,$A35),0)),"")
A40: =IFERROR(INDEX(상품!$M$7:$M$156,MATCH($A$35&"|"&3,상품!$N$7:$N$156,0)),"") | S40: 근거
B41: =IFERROR(INDEX(상품!$C$7:$C$156,MATCH($A$35&"|"&4,상품!$N$7:$N$156,0)),"") | C41: =IFERROR(INDEX(상품!$G$7:$G$156,MATCH($A$35&"|"&4,상품!$N$7:$N$156,0)),"") | D41: =IFERROR(INDEX(상품!$I$7:$I$156,MATCH($A$35&"|"&4,상품!$N$7:$N$156,0)),"") | E41: =IFERROR(INDEX(상품!$J$7:$J$156,MATCH($A$35&"|"&4,상품!$N$7:$N$156,0)),"") | F41: =IFERROR(INDEX(상품!$L$7:$L$156,MATCH($A$35&"|"&4,상품!$N$7:$N$156,0)),"") | G41: =IFERROR(IF(INDEX(상품!$C$7:$C$156,MATCH($A$35&"|"&4,상품!$N$7:$N$156,0))="","",ROUND($E$19/COUNTIFS(상품!$A$7:$A$156,"Y",상품!$B$7:$B$156,$A35),0)),"")
A42: =IFERROR(INDEX(상품!$M$7:$M$156,MATCH($A$35&"|"&4,상품!$N$7:$N$156,0)),"") | S42: 근거
B43: =IFERROR(INDEX(상품!$C$7:$C$156,MATCH($A$35&"|"&5,상품!$N$7:$N$156,0)),"") | C43: =IFERROR(INDEX(상품!$G$7:$G$156,MATCH($A$35&"|"&5,상품!$N$7:$N$156,0)),"") | D43: =IFERROR(INDEX(상품!$I$7:$I$156,MATCH($A$35&"|"&5,상품!$N$7:$N$156,0)),"") | E43: =IFERROR(INDEX(상품!$J$7:$J$156,MATCH($A$35&"|"&5,상품!$N$7:$N$156,0)),"") | F43: =IFERROR(INDEX(상품!$L$7:$L$156,MATCH($A$35&"|"&5,상품!$N$7:$N$156,0)),"") | G43: =IFERROR(IF(INDEX(상품!$C$7:$C$156,MATCH($A$35&"|"&5,상품!$N$7:$N$156,0))="","",ROUND($E$19/COUNTIFS(상품!$A$7:$A$156,"Y",상품!$B$7:$B$156,$A35),0)),"")
A44: =IFERROR(INDEX(상품!$M$7:$M$156,MATCH($A$35&"|"&5,상품!$N$7:$N$156,0)),"") | S44: 근거
A45: 해외주식 | B45: =IFERROR(INDEX(상품!$C$7:$C$156,MATCH($A$45&"|"&1,상품!$N$7:$N$156,0)),"") | C45: =IFERROR(INDEX(상품!$G$7:$G$156,MATCH($A$45&"|"&1,상품!$N$7:$N$156,0)),"") | D45: =IFERROR(INDEX(상품!$I$7:$I$156,MATCH($A$45&"|"&1,상품!$N$7:$N$156,0)),"") | E45: =IFERROR(INDEX(상품!$J$7:$J$156,MATCH($A$45&"|"&1,상품!$N$7:$N$156,0)),"") | F45: =IFERROR(INDEX(상품!$L$7:$L$156,MATCH($A$45&"|"&1,상품!$N$7:$N$156,0)),"") | G45: =IFERROR(IF(INDEX(상품!$C$7:$C$156,MATCH($A$45&"|"&1,상품!$N$7:$N$156,0))="","",ROUND($E$20/COUNTIFS(상품!$A$7:$A$156,"Y",상품!$B$7:$B$156,$A45),0)),"")
A46: =IFERROR(INDEX(상품!$M$7:$M$156,MATCH($A$45&"|"&1,상품!$N$7:$N$156,0)),"") | S46: 근거
B47: =IFERROR(INDEX(상품!$C$7:$C$156,MATCH($A$45&"|"&2,상품!$N$7:$N$156,0)),"") | C47: =IFERROR(INDEX(상품!$G$7:$G$156,MATCH($A$45&"|"&2,상품!$N$7:$N$156,0)),"") | D47: =IFERROR(INDEX(상품!$I$7:$I$156,MATCH($A$45&"|"&2,상품!$N$7:$N$156,0)),"") | E47: =IFERROR(INDEX(상품!$J$7:$J$156,MATCH($A$45&"|"&2,상품!$N$7:$N$156,0)),"") | F47: =IFERROR(INDEX(상품!$L$7:$L$156,MATCH($A$45&"|"&2,상품!$N$7:$N$156,0)),"") | G47: =IFERROR(IF(INDEX(상품!$C$7:$C$156,MATCH($A$45&"|"&2,상품!$N$7:$N$156,0))="","",ROUND($E$20/COUNTIFS(상품!$A$7:$A$156,"Y",상품!$B$7:$B$156,$A45),0)),"")
A48: =IFERROR(INDEX(상품!$M$7:$M$156,MATCH($A$45&"|"&2,상품!$N$7:$N$156,0)),"") | S48: 근거
...

Sheet 배분규칙
A1: 이 시트는 proposal_lib.py 가 셈한 배분입니다. 손으로 고치지 마십시오 — 고치면 화면(proposal.html)과 어긋납니다.
A3: 키 | B3: 성향 | C3: 기간 | D3: 국내주식 | E3: 해외주식 | F3: 국내ETF | G3: 해외ETF | H3: 국내펀드 | I3: 해외펀드 | J3: 현금
A4: 1|1 | B4: 1 | C4: 1년 이내 | D4: 0 | E4: 0 | F4: 0.02 | G4: 0.02 | H4: 0.08 | I4: 0.04 | J4: 0.84
A5: 1|3 | B5: 1 | C5: 3년 | D5: 0 | E5: 0 | F5: 0.035 | G5: 0.035 | H5: 0.14 | I5: 0.07 | J5: 0.72
A6: 1|5 | B6: 1 | C6: 5년 | D6: 0 | E6: 0 | F6: 0.045 | G6: 0.045 | H6: 0.18 | I6: 0.09 | J6: 0.64
A7: 1|10 | B7: 1 | C7: 5년 초과 | D7: 0 | E7: 0 | F7: 0.05 | G7: 0.05 | H7: 0.2 | I7: 0.1 | J7: 0.6
A8: 2|1 | B8: 2 | C8: 1년 이내 | D8: 0 | E8: 0.02 | F8: 0.04 | G8: 0.04 | H8: 0.1 | I8: 0.06 | J8: 0.74
A9: 2|3 | B9: 2 | C9: 3년 | D9: 0 | E9: 0.035 | F9: 0.07 | G9: 0.07 | H9: 0.175 | I9: 0.105 | J9: 0.545
A10: 2|5 | B10: 2 | C10: 5년 | D10: 0 | E10: 0.045 | F10: 0.09 | G10: 0.09 | H10: 0.225 | I10: 0.135 | J10: 0.415
A11: 2|10 | B11: 2 | C11: 5년 초과 | D11: 0 | E11: 0.05 | F11: 0.1 | G11: 0.1 | H11: 0.25 | I11: 0.15 | J11: 0.35
A12: 3|1 | B12: 3 | C12: 1년 이내 | D12: 0.02 | E12: 0.04 | F12: 0.06 | G12: 0.06 | H12: 0.08 | I12: 0.08 | J12: 0.66
A13: 3|3 | B13: 3 | C13: 3년 | D13: 0.035 | E13: 0.07 | F13: 0.105 | G13: 0.105 | H13: 0.14 | I13: 0.14 | J13: 0.405
A14: 3|5 | B14: 3 | C14: 5년 | D14: 0.045 | E14: 0.09 | F14: 0.135 | G14: 0.135 | H14: 0.18 | I14: 0.18 | J14: 0.235
A15: 3|10 | B15: 3 | C15: 5년 초과 | D15: 0.05 | E15: 0.1 | F15: 0.15 | G15: 0.15 | H15: 0.2 | I15: 0.2 | J15: 0.15
... A23: 5|10 | B23: 5 | C23: 5년 초과 | D23: 0.25 | E23: 0.3 | F23: 0.15 | G23: 0.2 | H23: 0.05 | I23: 0.05 | J23: 0

Sheet 자산군
A2: 1 | B2: 자산군 실측치
A4: 아래는 원천에서 실제로 잰 값입니다. 미래 수익률이 아닙니다. 빈칸(—)은 원천에 없어 셈하지 않은 것이며 만들어 넣지 않습니다.
A6: 자산군 | B6: 종목수 | C6: 수익률 산출 | D6: 과거 1년(중앙) | E6: 변동성(중앙) | F6: 최대낙폭(중앙)
A7: 국내ETF | B7: 78 | C7: 25 | D7: 0.14695507 | E7: 0.24025 | F7: -0.40630482
A8: 국내주식 | B8: 100 | C8: 100 | D8: 0.38298434 | E8: 0.56951225 | F8: -0.46758401
A9: 국내펀드 | B9: 526 | C9: 523 | D9: 0.294202 | E9: 0.18285 | F9: -0.1577
A10: 해외ETF | B10: 153 | C10: 60 | D10: 0.16738683 | E10: 0.1834939 | F10: -0.33717369
A11: 해외주식 | B11: 100 | C11: 99 | D11: 0.061489254 | E11: 0.29306841 | F11: -0.32494997
A12: 해외펀드 | B12: 434 | C12: 434 | D12: 0.104064 | E12: 0.1361 | F12: -0.11885
A13: 현금성 | B13: 112 | C13: 80 | D13: 0.0281925 | E13: 0.003 | F13: 0
A15: 펀드는 달 간격 기준가로 셈합니다 — 일봉보다 거칠어 최대낙폭이 다소 얕게 나옵니다. 계열이 없는 펀드는 원천이 준 누적 수익률과 52주 표준편차를 쓰고, 최대낙폭은 비워 둡니다.

Sheet 상품
A2: 2 | B2: 자산군별 제안 상품
A4: 여러 해의 위험조정 성과로 고릅니다 — 1·3·5 해의 연평균 수익률, 연변동성, 최대낙폭, 보수, 그리고 창이 바뀌어도 성과가 유지되는지를 함께 보아 점수를 냅니다. 지난해 수익률 순으로도, 규모 순으로도 고르지 않습니다 (규모는 문턱일 뿐입니다). 「측정」이 미측정인 상품은 시세가 없어 변동성·최대낙폭을 못 쟀습니다 — 잰 상품이 넉넉하면 후보에서 뺍니다. 적힌 수치는 모두 지나간 실적이며 미래 수익률이 아닙니다. 개별 주식은 종목 추천이 아닙니다.
A6: 채택 | B6: 자산군 | C6: 상품 | D6: 유형 | E6: 운용/발행 | F6: 규모 | G6: 측정 | H6: 잰 기간 | I6: 연평균 | J6: 변동성 | K6: 최대낙폭 | L6: 보수 | M6: 고른 까닭
A7: Y | B7: 국내주식 | C7: 우리금융지주 | D7: 금융 | E7: — | F7: 26조원 | G7: 다년 실측 | H7: 5해 | I7: 0.2601 | J7: 0.2987 | K7: -0.3395 | L7: — | M7: 5해 연26.0% · 변동성 29.9% (위험대비 0.78) · 최대낙폭 -34% · 가장 나쁜 창 연26.0% | N7: =IF($A7="Y",$B7&"|"&COUNTIFS($A$7:$A7,"Y",$B$7:$B7,$B7),"")
A8: Y | B8: 국내주식 | C8: KB금융 | D8: 금융 | E8: — | F8: 62조원 | G8: 다년 실측 | H8: 5해 | I8: 0.2678 | J8: 0.3533 | K8: -0.3359 | L8: — | M8: 5해 연26.8% · 변동성 35.3% (위험대비 0.68) · 최대낙폭 -34% · 가장 나쁜 창 연26.8% | N8: =IF($A8="Y",$B8&"|"&COUNTIFS($A$7:$A8,"Y",$B$7:$B8,$B8),"")
A9: N | B9: 국내주식 | C9: 신한지주 | D9: 금융 | E9: — | F9: 52조원 | G9: 다년 실측 | H9: 5해 | I9: 0.2321 | J9: 0.3143 | K9: -0.2899 | L9: — | M9: 5해 연23.2% · 변동성 31.4% (위험대비 0.65) · 최대낙폭 -29% · 가장 나쁜 창 연23.2% | N9: =IF($A9="Y",$B9&"|"&COUNTIFS($A$7:$A9,"Y",$B$7:$B9,$B9),"")
A10: N | B10: 국내주식 | C10: DB손해보험 | D10: 금융 | E10: — | F10: 11조원 | G10: 다년 실측 | H10: 5해 | I10: 0.2699 | J10: 0.3849 | K10: -0.3601 | L10: — | M10: 5해 연27.0% · 변동성 38.5% (위험대비 0.63) · 최대낙폭 -36% · 가장 나쁜 창 연27.0% | N10: =IF($A10="Y",$B10&"|"&COUNTIFS($A$7:$A10,"Y",$B$7:$B10,$B10),"")
A11: N | B11: 국내주식 | C11: 하나금융지주 | D11: 금융 | E11: — | F11: 36조원 | G11: 다년 실측 | H11: 5해 | I11: 0.2421 | J11: 0.3427 | K11: -0.354 | L11: — | M11: 5해 연24.2% · 변동성 34.3% (위험대비 0.62) · 최대낙폭 -35% · 가장 나쁜 창 연24.2% | N11: =IF($A11="Y",$B11&"|"&COUNTIFS($A$7:$A11,"Y",$B$7:$B11,$B11),"")
A12: Y | B12: 국내주식 | C12: KT&G | D12: 소비재 | E12: — | F12: 18조원 | G12: 다년 실측 | H12: 5해 | I12: 0.1542 | J12: 0.2396 | K12: -0.2301 | L12: — | M12: 5해 연15.4% · 변동성 24.0% (위험대비 0.53) · 최대낙폭 -23% · 가장 나쁜 창 연15.4% | N12: =IF($A12="Y",$B12&"|"&COUNTIFS($A$7:$A12,"Y",$B$7:$B12,$B12),"")
A13: Y | B13: 국내주식 | C13: LIG넥스원 | D13: 중공업 | E13: — | F13: 16조원 | G13: 다년 실측 | H13: 5해 | I13: 0.7317 | J13: 0.6138 | K13: -0.4223 | L13: — | M13: 5해 연73.2% · 변동성 61.4% (위험대비 1.15) · 최대낙폭 -42% · 가장 나쁜 창 연52.6% | N13: =IF($A13="Y",$B13&"|"&COUNTIFS($A$7:$A13,"Y",$B$7:$B13,$B13),"")
A14: N | B14: 국내주식 | C14: 삼성화재 | D14: 금융 | E14: — | F14: 29조원 | G14: 다년 실측 | H14: 5해 | I14: 0.2422 | J14: 0.4141 | K14: -0.3008 | L14: — | M14: 5해 연24.2% · 변동성 41.4% (위험대비 0.52) · 최대낙폭 -30% · 가장 나쁜 창 연24.2% | N14: =IF($A14="Y",$B14&"|"&COUNTIFS($A$7:$A14,"Y",$B$7:$B14,$B14),"")
A15: Y | B15: 국내주식 | C15: HD현대 | D15: 지주 | E15: — | F15: 15조원 | G15: 다년 실측 | H15: 5해 | I15: 0.2472 | J15: 0.3909 | K15: -0.3955 | L15: — | M15: 5해 연24.7% · 변동성 39.1% (위험대비 0.56) · 최대낙폭 -40% · 가장 나쁜 창 연24.7% | N15: =IF($A15="Y",$B15&"|"&COUNTIFS($A$7:$A15,"Y",$B$7:$B15,$B15),"")
A16: N | B16: 국내주식 | C16: GS | D16: 지주 | E16: — | F16: 11조원 | G16: 다년 실측 | H16: 5해 | I16: 0.2077 | J16: 0.3608 | K16: -0.3525 | L16: — | M16: 5해 연20.8% · 변동성 36.1% (위험대비 0.50) · 최대낙폭 -35% · 가장 나쁜 창 연20.8% | N16: =IF($A16="Y",$B16&"|"&COUNTIFS($A$7:$A16,"Y",$B$7:$B16,$B16),"")
A17: N | B17: 국내주식 | C17: SK하이닉스 | D17: 반도체 | E17: — | F17: 1,313조원 | G17: 다년 실측 | H17: 5해 | I17: 0.7096 | J17: 0.5455 | K17: -0.5471 | L17: — | M17: 5해 연71.0% · 변동성 54.5% (위험대비 1.25) · 최대낙폭 -55% · 가장 나쁜 창 연71.0% | N17: =IF($A17="Y",$B17&"|"&COUNTIFS($A$7:$A17,"Y",$B$7:$B17,$B17),"")
A18: N | B18: 국내주식 | C18: 한국항공우주 | D18: 중공업 | E18: — | F18: 13조원 | G18: 다년 실측 | H18: 5해 | I18: 0.3003 | J18: 0.4761 | K18: -0.4183 | L18: — | M18: 5해 연30.0% · 변동성 47.6% (위험대비 0.57) · 최대낙폭 -42% · 가장 나쁜 창 연30.0% | N18: =IF($A18="Y",$B18&"|"&COUNTIFS($A$7:$A18,"Y",$B$7:$B18,$B18),"")
... A56: N | B56: 해외주식 | C56: GE에어로스페이스 | D56: 산업재 | E56: — | F56: 441조원 | G56: 다년 실측 | H56: 5해 | I56: 0.4306 | J56: 0.3175 | K56: -0.383 | L56: — | M56: 5해 연43.1% · 변동성 31.8% (위험대비 1.27) · 최대낙폭 -38% · 가장 나쁜 창 연9.8% | N56: =IF($A56="Y",$B56&"|"&COUNTIFS($A$7:$A56,"Y",$B$7:$B56,$B56),"")
A57: Y | B57: 국내ETF | C57: PLUS 고배당주 | D57: 일반 | E57: 한화자산운용 | F57: 2조원 | G57: 다년 실측 | H57: 5해 | I57: 0.2077 | J57: 0.2007 | K57: -0.2069 | L57: 0.0023 | M57: 5해 연20.8% · 변동성 20.1% (위험대비 0.89) · 최대낙폭 -21% · 보수 0.23% · 가장 나쁜 창 연20.8% | N57: =IF($A57="Y",$B57&"|"&COUNTIFS($A$7:$A57,"Y",$B$7:$B57,$B57),"")
A58: Y | B58: 국내ETF | C58: KODEX 단기변동금리부채권액티브 | D58: 일반 | E58: 삼성자산운용(ETF) | F58: 2,797억원 | G58: 다년 실측 | H58: 5해 | I58: 0.0276 | J58: 0.0029 | K58: -0.0022 | L58: 0.0015 | M58: 5해 연2.8% · 변동성 0.3% (위험대비 -0.17) · 최대낙폭 -0% · 보수 0.15% · 가장 나쁜 창 연2.5% | N58: =IF($A58="Y",$B58&"|"&COUNTIFS($A$7:$A58,"Y",$B$7:$B58,$B58),"")
A59: Y | B59: 국내ETF | C59: TIGER 우량회사채액티브 | D59: 일반 | E59: 미래에셋자산운용 | F59: 4,999억원 | G59: 다년 실측 | H59: 3해 | I59: 0.0382 | J59: 0.0245 | K59: -0.0272 | L59: 0.001 | M59: 3해 연3.8% · 변동성 2.5% (위험대비 0.41) · 최대낙폭 -3% · 보수 0.10% · 가장 나쁜 창 연-1.3% | N59: =IF($A59="Y",$B59&"|"&COUNTIFS($A$7:$A59,"Y",$B$7:$B59,$B59),"")
A60: N | B60: 국내ETF | C60: RISE 중기우량회사채 | D60: 일반 | E60: KB자산운용 | F60: 2,987억원 | G60: 다년 실측 | H60: 5해 | I60: 0.02 | J60: 0.017 | K60: -0.0555 | L60: 0.0007 | M60: 5해 연2.0% · 변동성 1.7% (위험대비 -0.48) · 최대낙폭 -6% · 보수 0.07% · 가장 나쁜 창 연-0.8% | N60: =IF($A60="Y",$B60&"|"&COUNTIFS($A$7:$A60,"Y",$B$7:$B60,$B60),"")
A61: Y | B61: 국내ETF | C61: ACE KRX금현물 | D61: 일반 | E61: 한국투자신탁운용 | F61: 4조원 | G61: 다년 실측 | H61: 3해 | I61: 0.3125 | J61: 0.2508 | K61: -0.3209 | L61: 0.0019 | M61: 3해 연31.2% · 변동성 25.1% (위험대비 1.13) · 최대낙폭 -32% · 보수 0.19% · 가장 나쁜 창 연20.8% | N61: =IF($A61="Y",$B61&"|"&COUNTIFS($A$7:$A61,"Y",$B$7:$B61,$B61),"")
A62: Y | B62: 국내ETF | C62: KODEX 은행 | D62: 일반 | E62: 삼성자산운용(ETF) | F62: 2,941억원 | G62: 다년 실측 | H62: 5해 | I62: 0.23 | J62: 0.2703 | K62: -0.3205 | L62: 0.003 | M62: 5해 연23.0% · 변동성 27.0% (위험대비 0.75) · 최대낙폭 -32% · 보수 0.30% · 가장 나쁜 창 연23.0% | N62: =IF($A62="Y",$B62&"|"&COUNTIFS($A$7:$A62,"Y",$B$7:$B62,$B62),"")
A63: N | B63: 국내ETF | C63: SOL 종합채권(AA-이상)액티브 | D63: 일반 | E63: 신한자산운용 | F63: 1조원 | G63: 다년 실측 | H63: 3해 | I63: 0.0213 | J63: 0.0485 | K63: -0.075 | L63: 0.0004 | M63: 3해 연2.1% · 변동성 4.8% (위험대비 -0.14) · 최대낙폭 -8% · 보수 0.04% · 가장 나쁜 창 연-6.0% | N63: =IF($A63="Y",$B63&"|"&COUNTIFS($A$7:$A63,"Y",$B$7:$B63,$B63),"")
A64: N | B64: 국내ETF | C64: TIGER 종합채권(AA-이상)액티브 | D64: 일반 | E64: 미래에셋자산운용 | F64: 1조원 | G64: 다년 실측 | H64: 3해 | I64: 0.0211 | J64: 0.0371 | K64: -0.0762 | L64: 0.0003 | M64: 3해 연2.1% · 변동성 3.7% (위험대비 -0.19) · 최대낙폭 -8% · 보수 0.03% · 가장 나쁜 창 연-6.1% | N64: =IF($A64="Y",$B64&"|"&COUNTIFS($A$7:$A64,"Y",$B$7:$B64,$B64),"")
A65: N | B65: 국내ETF | C65: RISE 삼성그룹Top3채권혼합 | D65: 일반 | E65: KB자산운용 | F65: 3,260억원 | G65: 다년 실측 | H65: 3해 | I65: 0.14 | J65: 0.1362 | K65: -0.1117 | L65: 0.002 | M65: 3해 연14.0% · 변동성 13.6% (위험대비 0.82) · 최대낙폭 -11% · 보수 0.20% · 가장 나쁜 창 연14.0% | N65: =IF($A65="Y",$B65&"|"&COUNTIFS($A$7:$A65,"Y",$B$7:$B65,$B65),"")
A66: N | B66: 국내ETF | C66: PLUS 고배당주채권혼합 | D66: 일반 | E66: 한화자산운용 | F66: 5,956억원 | G66: 다년 실측 | H66: 5해 | I66: 0.094 | J66: 0.0934 | K66: -0.1106 | L66: 0.002 | M66: 5해 연9.4% · 변동성 9.3% (위험대비 0.71) · 최대낙폭 -11% · 보수 0.20% · 가장 나쁜 창 연9.4% | N66: =IF($A66="Y",$B66&"|"&COUNTIFS($A$7:$A66,"Y",$B$7:$B66,$B66),"")
A67: N | B67: 국내ETF | C67: ACE 종합채권(AA-이상)액티브 | D67: 일반 | E67: 한국투신운용(ETF) | F67: 1조원 | G67: 다년 실측 | H67: 5해 | I67: 0.0059 | J67: 0.0423 | K67: -0.114 | L67: 0.0002 | M67: 5해 연0.6% · 변동성 4.2% (위험대비 -0.52) · 최대낙폭 -11% · 보수 0.02% · 가장 나쁜 창 연-5.9% | N67: =IF($A67="Y",$B67&"|"&COUNTIFS($A$7:$A67,"Y",$B$7:$B67,$B67),"")
A68: N | B68: 국내ETF | C68: ACE 국고채10년 | D68: 일반 | E68: 한국투신운용(ETF) | F68: 5,152억원 | G68: 다년 실측 | H68: 5해 | I68: -0.0101 | J68: 0.0683 | K68: -0.1778 | L68: 0.0002 | M68: 5해 연-1.0% · 변동성 6.8% (위험대비 -0.56) · 최대낙폭 -18% · 보수 0.02% · 가장 나쁜 창 연-7.8% | N68: =IF($A68="Y",$B68&"|"&COUNTIFS($A$7:$A68,"Y",$B$7:$B68,$B68),"")
A69: N | B69: 국내ETF | C69: KIWOOM 국고채10년 | D69: 일반 | E69: 키움투자자산운용 | F69: 4,141억원 | G69: 다년 실측 | H69: 5해 | I69: -0.0107 | J69: 0.0681 | K69: -0.1803 | L69: 0.0005 | M69: 5해 연-1.1% · 변동성 6.8% (위험대비 -0.57) · 최대낙폭 -18% · 보수 0.05% · 가장 나쁜 창 연-7.9% | N69: =IF($A69="Y",$B69&"|"&COUNTIFS($A$7:$A69,"Y",$B$7:$B69,$B69),"")
A70: N | B70: 국내ETF | C70: SOL 국제금 | D70: 일반 | E70: 신한자산운용 | F70: 922억원 | G70: 미측정 | H70: — | I70: — | J70: — | K70: — | L70: 0.0005 | M70: 보수 0.05% · 시세가 없어 변동성·낙폭을 못 쟀습니다 | N70: =IF($A70="Y",$B70&"|"&COUNTIFS($A$7:$A70,"Y",$B$7:$B70,$B70),"")
A71: N | B71: 국내ETF | C71: SOL 200 Top10 | D71: 대형주TOP10 | E71: — | F71: — | G71: 다년 실측 | H71: 3해 | I71: 0.2455 | J71: 0.3238 | K71: -0.3451 | L71: — | M71: 3해 연24.6% · 변동성 32.4% (위험대비 0.67) · 최대낙폭 -35% · 가장 나쁜 창 연24.6% | N71: =IF($A71="Y",$B71&"|"&COUNTIFS($A$7:$A71,"Y",$B$7:$B71,$B71),"")
A72: N | B72: 국내ETF | C72: KIWOOM 단기자금 | D72: 일반 | E72: 키움투자자산운용 | F72: 681억원 | G72: 다년 실측 | H72: 5해 | I72: 0.027 | J72: 0.0056 | K72: -0.0077 | L72: 0.0005 | M72: 5해 연2.7% · 변동성 0.6% (위험대비 -0.20) · 최대낙폭 -1% · 보수 0.05% · 가장 나쁜 창 연2.4% | N72: =IF($A72="Y",$B72&"|"&COUNTIFS($A$7:$A72,"Y",$B$7:$B72,$B72),"")
A73: N | B73: 국내ETF | C73: TIGER 반도체TOP10 | D73: 반도체/IT | E73: — | F73: — | G73: 다년 실측 | H73: 3해 | I73: 0.5674 | J73: 0.5171 | K73: -0.5251 | L73: — | M73: 3해 연56.7% · 변동성 51.7% (위험대비 1.04) · 최대낙폭 -53% · 가장 나쁜 창 연56.7% | N73: =IF($A73="Y",$B73&"|"&COUNTIFS($A$7:$A73,"Y",$B$7:$B73,$B73),"")
A74: N | B74: 국내ETF | C74: TIGER 코리아TOP10 | D74: 대형주TOP10 | E74: — | F74: — | G74: 다년 실측 | H74: 5해 | I74: 0.2219 | J74: 0.3274 | K74: -0.4009 | L74: — | M74: 5해 연22.2% · 변동성 32.7% (위험대비 0.59) · 최대낙폭 -40% · 가장 나쁜 창 연22.2% | N74: =IF($A74="Y",$B74&"|"&COUNTIFS($A$7:$A74,"Y",$B$7:$B74,$B74),"")
A75: N | B75: 국내ETF | C75: ACE 코스피 | D75: KOSPI | E75: — | F75: — | G75: 다년 실측 | H75: 5해 | I75: 0.1846 | J75: 0.2839 | K75: -0.3849 | L75: — | M75: 5해 연18.5% · 변동성 28.4% (위험대비 0.55) · 최대낙폭 -38% · 가장 나쁜 창 연18.5% | N75: =IF($A75="Y",$B75&"|"&COUNTIFS($A$7:$A75,"Y",$B$7:$B75,$B75),"")
A76: N | B76: 국내ETF | C76: TIGER K방산&우주 | D76: K-우주방산 | E76: — | F76: — | G76: 다년 실측 | H76: 3해 | I76: 0.4601 | J76: 0.4922 | K76: -0.4614 | L76: — | M76: 3해 연46.0% · 변동성 49.2% (위험대비 0.88) · 최대낙폭 -46% · 가장 나쁜 창 연17.8% | N76: =IF($A76="Y",$B76&"|"&COUNTIFS($A$7:$A76,"Y",$B$7:$B76,$B76),"")
A77: N | B77: 국내ETF | C77: TIGER 중장기국채 | D77: 채권형 | E77: — | F77: — | G77: 다년 실측 | H77: 5해 | I77: 0.0007 | J77: 0.0451 | K77: -0.1197 | L77: — | M77: 5해 연0.1% · 변동성 4.5% (위험대비 -0.61) · 최대낙폭 -12% · 가장 나쁜 창 연-4.5% | N77: =IF($A77="Y",$B77&"|"&COUNTIFS($A$7:$A77,"Y",$B$7:$B77,$B77),"")
A78: N | B78: 국내ETF | C78: TIGER 코스닥150 | D78: KOSDAQ | E78: — | F78: — | G78: 다년 실측 | H78: 5해 | I78: -0.0109 | J78: 0.3528 | K78: -0.4959 | L78: — | M78: 5해 연-1.1% · 변동성 35.3% (위험대비 -0.11) · 최대낙폭 -50% · 가장 나쁜 창 연-2.1% | N78: =IF($A78="Y",$B78&"|"&COUNTIFS($A$7:$A78,"Y",$B$7:$B78,$B78),"")
A79: N | B79: 국내ETF | C79: TIGER 배당커버드콜액티브 | D79: 배당/커버드콜 | E79: — | F79: — | G79: 1해 실측 | H79: 1해 | I79: 1.2274 | J79: 0.5555 | K79: -0.4064 | L79: — | M79: 1해 연122.7% · 변동성 55.5% (위험대비 2.16) · 최대낙폭 -41% | N79: =IF($A79="Y",$B79&"|"&COUNTIFS($A$7:$A79,"Y",$B$7:$B79,$B79),"")
A80: N | B80: 국내ETF | C80: TIGER 코리아테크액티브 | D80: 반도체/IT | E80: — | F80: — | G80: 1해 실측 | H80: 1해 | I80: 2.1087 | J80: 0.6484 | K80: -0.4977 | L80: — | M80: 1해 연210.9% · 변동성 64.8% (위험대비 3.21) · 최대낙폭 -50% | N80: =IF($A80="Y",$B80&"|"&COUNTIFS($A$7:$A80,"Y",$B$7:$B80,$B80),"")
...

Sheet 출처
A2: 3 | B2: 자료 출처와 기준일
A4: 자산군 | B4: 원천 | C4: 종목 | D4: 기준일 | E4: 비고
A5: 펀드 | B5: 네이버 Npay 증권 + 금융투자협회 전자공시(투자지역) | C5: 1054 | D5: 2026-09-21 | E5: 보수는 클래스마다 달라 하나로 줄이지 않고 범위(feeMin~feeMax)로 싣습니다. 기간수익률은 **누적**입니다(ETF 는 연율이라 뜻이 다릅니다). 변동성·최대낙폭은 달 간격 기준가 계열에서 셈하고, 계열이 없으면 원천의 52 주 표준편차를 씁니다.
A6: 국내주식 | B6: 한국투자증권 오픈API (모의투자) — 100 종 (나머지 0 종은 야후 파이낸스) | C6: 100 | D6: 2026-09-18 | E6: 야후·네이버를 증권사 값으로 심판한 결과(data/prices_kis/verdict.txt) 야후가 갈리는 봉의 89.1%에서 틀렸으므로, 국내주식은 증권사 일봉으로 갈아 끼웠습니다. 시가총액도 같은 종가로 고쳐 셈했습니다.
A7: 해외주식 | B7: 야후 파이낸스 일봉 (자료 가지 us100-data) | C7: 100 | D7: 2026-09-29
A8: 국내ETF | B8: 네이버 금융 일봉 + 야후 차트 일봉(close, 배당 미보정) + ETFCHECK (https://www.etfcheck.co.kr) | C8: 247 | D8: 2026-09-29
A9: 해외ETF | B9: 한국투자증권 오픈API (모의투자, HHDFS76240000, 수정주가) | C9: 19 | D9: 2026-09-20
A12: 이 자료가 지키는 규칙
A13: 수익률계열 | B13: 주식·ETF 는 일봉에서 직접 셈합니다(최근 252 거래일). 펀드는 원천이 주는 1 년 수익률을 씁니다 — 두 계열은 기준일이 다를 수 있으므로 상품마다 asOf 를 답니다.
A14: 변동성 | B14: 일봉이 있는 상품만 연변동성(일간 로그수익률 표준편차 × √252)을 셈합니다. 펀드는 달 간격 기준가로 셈하고, 계열이 원천의 위험등급을 씁니다.
A15: 펀드보수 | B15: 클래스마다 달라 하나로 줄이지 않고 범위로 싣습니다.
A16: 해외펀드 | B16: 해외에 설정된 뮤추얼펀드가 아니라 해외에 투자하는, 국내 설정 공모펀드입니다.
A17: 최소설정액 | B17: 10000000000

Sheet 기대수익률
A2: 1 | B2: 자산군별 기대수익률 — 두 방식
A4: 기대수익률은 재는 것이 아니라 가정하는 것입니다. 서로 다른 두 길로 세워 보고 어긋나는 곳을 함께 적습니다.
A6: 자산군 | B6: ① 빌딩블록 | C6: ② 장기실적(8년) | D6: 차이 | E6: 비고
A7: 국내주식 | B7: 0.0781 | C7: 0.1488 | D7: 0.0707
A8: 해외주식 | B8: 0.0781 | C8: 0.1849 | D8: 0.1068
A9: 국내채권 | B9: 0.0361 | C9: 0.0105 | D9: -0.0256
A10: 해외채권 | B10: 0.0381 | C10: -0.0601 | D10: -0.0982
A11: 대체 | B11: 0.0481 | C11: 0.0939 | D11: 0.0458
A12: 현금성 | B12: 0.0281 | C12: 0.0281 | D12: 0
A14: · ① 무위험수익률 2.81% 는 짐작이 아니라 MMF 80종의 1년 수익률 중앙값(실측)입니다.
A15: · ① 의 리스크프리미엄은 가정입니다. 회사 자산배분본부의 장기 기대수익률(CMA)이 있으면 scripts/proposal_cma.py 의 PREMIUM 을 그 값으로 바꾸십시오 — 화면과 엑셀이 함께 따라옵니다.
A16: · ② 를 기준선으로 쓰지 않는 까닭: 창(2018~2026)이 강세장 한 국면에 갇혀 있어 주식이 18%대로 나오고, 같은 국내주식인데 프록시에 따라 TIGER 200 19.8% · 코스닥150 1.8% 로 20%p 가 갈립니다. 해외채권·대체는 5해를 채우는 원화 프록시가 없어 아예 덮지 못합니다.
A17: · ② 는 분배금이 빠진 가격 수익률이라 실제보다 낮게 나옵니다. 국내채권이 1.05%로 나오는 것이 그 편향입니다.
A18: · 달러 표시 ETF 로 장기 실적을 재지 않았습니다. 그 값은 환율이 빠진 달러 투자자의 수익률이지 한국 고객의 수익률이 아닙니다.
A21: 2 | B21: 제안 자산군에 적용한 값
A23: 자산군(국내ETF·해외펀드…)은 포장지라 그 자체로 기대수익률이 없습니다. 그 칸에 담긴 상품의 실제 노출로 위 ① 값을 섞어 낸 것입니다.
A25: 자산군 | B25: 기대수익률(가정) | C25: 섞은 노출
A26: 국내주식 | B26: 0.0781 | C26: 국내주식 100%
A27: 해외주식 | B27: 0.0781 | C27: 해외주식 100%
A28: 국내ETF | B28: 0.0553 | C28: 국내주식 40% · 국내채권 40% · 대체 20%
A29: 해외ETF | B29: 0.0561 | C29: 해외주식 40% · 해외채권 40% · 대체 20%
A30: 국내펀드 | B30: 0.0451 | C30: 국내채권 50% · 대체 40% · 국내주식 10%
A31: 해외펀드 | B31: 0.0561 | C31: 해외채권 40% · 해외주식 40% · 대체 20%
A32: 현금 | B32: 0.0281 | C32: 현금성 100%

Sheet 사용법
B2: 쓰는 법
B4: 1. 「제안서」 시트에서 파란 글씨 칸만 고칩니다 — 고객명·투자금액·투자기간·위험성향·목표 연수익률. 투자기간과 위험성향은 드롭다운입니다.
B5: 1-1. 조건을 다 넣으셨으면 「조회」 칸에서 ▶ 조회 실행 을 고릅니다. … 조건 입력 중 로 두면 표가 비워져 조건만 차분히 채울 수 있습니다. 매크로 없는 .xlsx 에는 누르는 단추를 넣을 수 없어 드롭다운으로 만들었습니다 — .xlsm 으로 만들면 회사 PC 에서 매크로가 막혀 열자마자 「사용 안 함」이 뜹니다.
B6: 1-2. 「목표 연수익률」은 고객이 바라는 수익률이고, 배분표의 「기대수익률 (가정)」은 그것을 어떻게 벌 작정인지에 대한 자산군별 가정입니다. 둘은 다른 것이며, 3 번 섹션이 둘을 견주어 줍니다.
B7: 2. 나머지 칸은 수식입니다. 손으로 덮어쓰면 다음에 값이 안 따라옵니다.
B8: 3. 「배분규칙」 시트는 proposal_lib.py 가 셈한 것입니다. 고치지 마십시오 — 고치면 화면(proposal.html)과 어긋납니다.
B9: 4. 「기대수익률 (가정)」 칸은 비워 두었습니다. 사람이 넣는 가정이며 기본값을 두지 않았습니다 — 넣으실 때 근거를 함께 적어 두십시오.
B10: 5. 자료를 새로 받으면 python3 scripts/build_proposal_universe.py 를 돌린 뒤 이 파일을 다시 만듭니다.
B12: 셀 색 규칙 (기존 고객제안서와 같습니다)
B13: 파란 글씨 + 옅은 칠 = 사람이 넣는 칸
B14: 검은 글씨 = 수식
B15: 회색 글씨 = 원천에서 받아 적은 값
B17: 숨은 H·I 열은 셈에 쓰는 도우미 칸입니다 — 합계용 숫자(표시 칸에 「—」라는 글자가 들어가면 합계가 깨집니다), 성향 번호, 조회 키, 목표 역산. 지우지 마십시오.
