Workbook
Name 선택가능종목: 'ETF데이터'!$A$4:$A$594
Name 검색어: '제안서'!$E$17
Name 검색건수: COUNTIF('ETF데이터'!$AC$4:$AC$594,1)
Name 검색결과: OFFSET('ETF데이터'!$AE$4,0,0,MAX(1,COUNTIF('ETF데이터'!$AC$4:$AC$594,1)),1)
Name 담긴목록: '종목조회'!$R$20:$R$79
Name 담긴수: '종목조회'!$Q$79
Name 조회_주기: '종목조회'!$C$10
Name 조회_최소: '종목조회'!$C$11
Name 조회_최대: '종목조회'!$C$12

Sheet 제안서
A1: 사내한 · Confidential | J1: 계산 보조 (수정하지 마십시오)
A2: 월배당 ETF 투자 제안서
A3: Monthly Distribution ETF Portfolio
A5: 자료 ETFCHECK · 기준일 2026-10-02 · 매월 1일 자동 갱신
A8: 1 | B8: 고객 정보 및 투자 조건
B10: 고객명 | C10: 홍길동
B11: 총 투자금액 (원) | C11: 100000000
B12: 배분 방식 | C12: 비율 | E12: 비율 = 총액을 %로 나눔 · 금액 = 종목별 금액 직접 입력
B13: 배당소득세율 | C13: 0.154 | E13: 국내 상장 ETF 분배금 기준 15.4% (지방소득세 포함)
B14: 제안일 | C14: 2026-10-04
A17: 2 | B17: 투자 포트폴리오 (최대 10종목) | D17: 종목 검색 | F17: =IF(검색어="","← 글자 일부를 넣으면 아래 '투자 ETF' 의 ▼ 목록이 그만큼만 남습니다 (예: 커버드콜)",IF(검색건수=0,"→ '"&검색어&"' 에 맞는 종목이 없습니다. 글자를 줄여 보십시오.","→ '"&검색어&"' 로 "&검색건수&"종목. 아래 '투자 ETF' 칸의 ▼ 를 누르십시오."))
B19: 투자 ETF | C19: =IF($C$12="비율","배분 비율 (%)","배분 금액 (원)") | D19: 배정 금액 | E19: 매수 수량 | F19: 실투자금액 | G19: 월 분배금(세전) | H19: 월 분배금(세후)
B20: =IF(담긴수=0,"TIGER 미국배당다우존스",IFERROR(INDEX(담긴목록,1),"")) | C20: =IF($B20="","",IF($C$12="비율",IF(1<MAX(담긴수,1),ROUND(100/MAX(담긴수,1),2),100-ROUND(100/MAX(담긴수,1),2)*(MAX(담긴수,1)-1)),IF(1<MAX(담긴수,1),ROUNDDOWN($C$11/MAX(담긴수,1),0),$C$11-ROUNDDOWN($C$11/MAX(담긴수,1),0)*(MAX(담긴수,1)-1)))) | D20: =IF($K20=0,0,IF($C$12="비율",ROUND($C$11*$C20/100,0),$C20)) | E20: =IF($K20=0,0,ROUNDDOWN($D20/INDEX('ETF데이터'!$D$4:$D$594,$K20),0)) | F20: =IF($K20=0,0,$E20*INDEX('ETF데이터'!$D$4:$D$594,$K20)) | G20: =IF($K20=0,0,$F20*INDEX('ETF데이터'!$J$4:$J$594,$K20)/12) | H20: =$G20*(1-$C$13*$O20) | K20: =IF($B20="",0,IFERROR(MATCH($B20,선택가능종목,0),0)) | L20: =IF($K20=0,"",INDEX('ETF데이터'!$M$4:$M$594,$K20)) | M20: =IF($K20=0,"",INDEX('ETF데이터'!$R$4:$R$594,$K20)) | N20: =IF(OR($M20="",$M20="월배당"),0,1) | O20: =IF($K20=0,1,IF(INDEX('ETF데이터'!$T$4:$T$594,$K20)="",1,INDEX('ETF데이터'!$T$4:$T$594,$K20))) | P20: =IF($K20=0,0,IF(INDEX('ETF데이터'!$T$4:$T$594,$K20)="",1,0))
B21: =IF(담긴수=0,"",IFERROR(INDEX(담긴목록,2),"")) | C21: =IF($B21="","",IF($C$12="비율",IF(2<MAX(담긴수,1),ROUND(100/MAX(담긴수,1),2),100-ROUND(100/MAX(담긴수,1),2)*(MAX(담긴수,1)-1)),IF(2<MAX(담긴수,1),ROUNDDOWN($C$11/MAX(담긴수,1),0),$C$11-ROUNDDOWN($C$11/MAX(담긴수,1),0)*(MAX(담긴수,1)-1)))) | D21: =IF($K21=0,0,IF($C$12="비율",ROUND($C$11*$C21/100,0),$C21)) | E21: =IF($K21=0,0,ROUNDDOWN($D21/INDEX('ETF데이터'!$D$4:$D$594,$K21),0)) | F21: =IF($K21=0,0,$E21*INDEX('ETF데이터'!$D$4:$D$594,$K21)) | G21: =IF($K21=0,0,$F21*INDEX('ETF데이터'!$J$4:$J$594,$K21)/12) | H21: =$G21*(1-$C$13*$O21) | K21: =IF($B21="",0,IFERROR(MATCH($B21,선택가능종목,0),0)) | L21: =IF($K21=0,"",INDEX('ETF데이터'!$M$4:$M$594,$K21)) | M21: =IF($K21=0,"",INDEX('ETF데이터'!$R$4:$R$594,$K21)) | N21: =IF(OR($M21="",$M21="월배당"),0,1) | O21: =IF($K21=0,1,IF(INDEX('ETF데이터'!$T$4:$T$594,$K21)="",1,INDEX('ETF데이터'!$T$4:$T$594,$K21))) | P21: =IF($K21=0,0,IF(INDEX('ETF데이터'!$T$4:$T$594,$K21)="",1,0))
B22: =IF(담긴수=0,"",IFERROR(INDEX(담긴목록,3),"")) | C22: =IF($B22="","",IF($C$12="비율",IF(3<MAX(담긴수,1),ROUND(100/MAX(담긴수,1),2),100-ROUND(100/MAX(담긴수,1),2)*(MAX(담긴수,1)-1)),IF(3<MAX(담긴수,1),ROUNDDOWN($C$11/MAX(담긴수,1),0),$C$11-ROUNDDOWN($C$11/MAX(담긴수,1),0)*(MAX(담긴수,1)-1)))) | D22: =IF($K22=0,0,IF($C$12="비율",ROUND($C$11*$C22/100,0),$C22)) | E22: =IF($K22=0,0,ROUNDDOWN($D22/INDEX('ETF데이터'!$D$4:$D$594,$K22),0)) | F22: =IF($K22=0,0,$E22*INDEX('ETF데이터'!$D$4:$D$594,$K22)) | G22: =IF($K22=0,0,$F22*INDEX('ETF데이터'!$J$4:$J$594,$K22)/12) | H22: =$G22*(1-$C$13*$O22) | K22: =IF($B22="",0,IFERROR(MATCH($B22,선택가능종목,0),0)) | L22: =IF($K22=0,"",INDEX('ETF데이터'!$M$4:$M$594,$K22)) | M22: =IF($K22=0,"",INDEX('ETF데이터'!$R$4:$R$594,$K22)) | N22: =IF(OR($M22="",$M22="월배당"),0,1) | O22: =IF($K22=0,1,IF(INDEX('ETF데이터'!$T$4:$T$594,$K22)="",1,INDEX('ETF데이터'!$T$4:$T$594,$K22))) | P22: =IF($K22=0,0,IF(INDEX('ETF데이터'!$T$4:$T$594,$K22)="",1,0))
B23: =IF(담긴수=0,"",IFERROR(INDEX(담긴목록,4),"")) | C23: =IF($B23="","",IF($C$12="비율",IF(4<MAX(담긴수,1),ROUND(100/MAX(담긴수,1),2),100-ROUND(100/MAX(담긴수,1),2)*(MAX(담긴수,1)-1)),IF(4<MAX(담긴수,1),ROUNDDOWN($C$11/MAX(담긴수,1),0),$C$11-ROUNDDOWN($C$11/MAX(담긴수,1),0)*(MAX(담긴수,1)-1)))) | D23: =IF($K23=0,0,IF($C$12="비율",ROUND($C$11*$C23/100,0),$C23)) | E23: =IF($K23=0,0,ROUNDDOWN($D23/INDEX('ETF데이터'!$D$4:$D$594,$K23),0)) | F23: =IF($K23=0,0,$E23*INDEX('ETF데이터'!$D$4:$D$594,$K23)) | G23: =IF($K23=0,0,$F23*INDEX('ETF데이터'!$J$4:$J$594,$K23)/12) | H23: =$G23*(1-$C$13*$O23) | K23: =IF($B23="",0,IFERROR(MATCH($B23,선택가능종목,0),0)) | L23: =IF($K23=0,"",INDEX('ETF데이터'!$M$4:$M$594,$K23)) | M23: =IF($K23=0,"",INDEX('ETF데이터'!$R$4:$R$594,$K23)) | N23: =IF(OR($M23="",$M23="월배당"),0,1) | O23: =IF($K23=0,1,IF(INDEX('ETF데이터'!$T$4:$T$594,$K23)="",1,INDEX('ETF데이터'!$T$4:$T$594,$K23))) | P23: =IF($K23=0,0,IF(INDEX('ETF데이터'!$T$4:$T$594,$K23)="",1,0))
B24: =IF(담긴수=0,"",IFERROR(INDEX(담긴목록,5),"")) | C24: =IF($B24="","",IF($C$12="비율",IF(5<MAX(담긴수,1),ROUND(100/MAX(담긴수,1),2),100-ROUND(100/MAX(담긴수,1),2)*(MAX(담긴수,1)-1)),IF(5<MAX(담긴수,1),ROUNDDOWN($C$11/MAX(담긴수,1),0),$C$11-ROUNDDOWN($C$11/MAX(담긴수,1),0)*(MAX(담긴수,1)-1)))) | D24: =IF($K24=0,0,IF($C$12="비율",ROUND($C$11*$C24/100,0),$C24)) | E24: =IF($K24=0,0,ROUNDDOWN($D24/INDEX('ETF데이터'!$D$4:$D$594,$K24),0)) | F24: =IF($K24=0,0,$E24*INDEX('ETF데이터'!$D$4:$D$594,$K24)) | G24: =IF($K24=0,0,$F24*INDEX('ETF데이터'!$J$4:$J$594,$K24)/12) | H24: =$G24*(1-$C$13*$O24) | K24: =IF($B24="",0,IFERROR(MATCH($B24,선택가능종목,0),0)) | L24: =IF($K24=0,"",INDEX('ETF데이터'!$M$4:$M$594,$K24)) | M24: =IF($K24=0,"",INDEX('ETF데이터'!$R$4:$R$594,$K24)) | N24: =IF(OR($M24="",$M24="월배당"),0,1) | O24: =IF($K24=0,1,IF(INDEX('ETF데이터'!$T$4:$T$594,$K24)="",1,INDEX('ETF데이터'!$T$4:$T$594,$K24))) | P24: =IF($K24=0,0,IF(INDEX('ETF데이터'!$T$4:$T$594,$K24)="",1,0))
B25: =IF(담긴수=0,"",IFERROR(INDEX(담긴목록,6),"")) | C25: =IF($B25="","",IF($C$12="비율",IF(6<MAX(담긴수,1),ROUND(100/MAX(담긴수,1),2),100-ROUND(100/MAX(담긴수,1),2)*(MAX(담긴수,1)-1)),IF(6<MAX(담긴수,1),ROUNDDOWN($C$11/MAX(담긴수,1),0),$C$11-ROUNDDOWN($C$11/MAX(담긴수,1),0)*(MAX(담긴수,1)-1)))) | D25: =IF($K25=0,0,IF($C$12="비율",ROUND($C$11*$C25/100,0),$C25)) | E25: =IF($K25=0,0,ROUNDDOWN($D25/INDEX('ETF데이터'!$D$4:$D$594,$K25),0)) | F25: =IF($K25=0,0,$E25*INDEX('ETF데이터'!$D$4:$D$594,$K25)) | G25: =IF($K25=0,0,$F25*INDEX('ETF데이터'!$J$4:$J$594,$K25)/12) | H25: =$G25*(1-$C$13*$O25) | K25: =IF($B25="",0,IFERROR(MATCH($B25,선택가능종목,0),0)) | L25: =IF($K25=0,"",INDEX('ETF데이터'!$M$4:$M$594,$K25)) | M25: =IF($K25=0,"",INDEX('ETF데이터'!$R$4:$R$594,$K25)) | N25: =IF(OR($M25="",$M25="월배당"),0,1) | O25: =IF($K25=0,1,IF(INDEX('ETF데이터'!$T$4:$T$594,$K25)="",1,INDEX('ETF데이터'!$T$4:$T$594,$K25))) | P25: =IF($K25=0,0,IF(INDEX('ETF데이터'!$T$4:$T$594,$K25)="",1,0))
B26: =IF(담긴수=0,"",IFERROR(INDEX(담긴목록,7),"")) | C26: =IF($B26="","",IF($C$12="비율",IF(7<MAX(담긴수,1),ROUND(100/MAX(담긴수,1),2),100-ROUND(100/MAX(담긴수,1),2)*(MAX(담긴수,1)-1)),IF(7<MAX(담긴수,1),ROUNDDOWN($C$11/MAX(담긴수,1),0),$C$11-ROUNDDOWN($C$11/MAX(담긴수,1),0)*(MAX(담긴수,1)-1)))) | D26: =IF($K26=0,0,IF($C$12="비율",ROUND($C$11*$C26/100,0),$C26)) | E26: =IF($K26=0,0,ROUNDDOWN($D26/INDEX('ETF데이터'!$D$4:$D$594,$K26),0)) | F26: =IF($K26=0,0,$E26*INDEX('ETF데이터'!$D$4:$D$594,$K26)) | G26: =IF($K26=0,0,$F26*INDEX('ETF데이터'!$J$4:$J$594,$K26)/12) | H26: =$G26*(1-$C$13*$O26) | K26: =IF($B26="",0,IFERROR(MATCH($B26,선택가능종목,0),0)) | L26: =IF($K26=0,"",INDEX('ETF데이터'!$M$4:$M$594,$K26)) | M26: =IF($K26=0,"",INDEX('ETF데이터'!$R$4:$R$594,$K26)) | N26: =IF(OR($M26="",$M26="월배당"),0,1) | O26: =IF($K26=0,1,IF(INDEX('ETF데이터'!$T$4:$T$594,$K26)="",1,INDEX('ETF데이터'!$T$4:$T$594,$K26))) | P26: =IF($K26=0,0,IF(INDEX('ETF데이터'!$T$4:$T$594,$K26)="",1,0))
B27: =IF(담긴수=0,"",IFERROR(INDEX(담긴목록,8),"")) | C27: =IF($B27="","",IF($C$12="비율",IF(8<MAX(담긴수,1),ROUND(100/MAX(담긴수,1),2),100-ROUND(100/MAX(담긴수,1),2)*(MAX(담긴수,1)-1)),IF(8<MAX(담긴수,1),ROUNDDOWN($C$11/MAX(담긴수,1),0),$C$11-ROUNDDOWN($C$11/MAX(담긴수,1),0)*(MAX(담긴수,1)-1)))) | D27: =IF($K27=0,0,IF($C$12="비율",ROUND($C$11*$C27/100,0),$C27)) | E27: =IF($K27=0,0,ROUNDDOWN($D27/INDEX('ETF데이터'!$D$4:$D$594,$K27),0)) | F27: =IF($K27=0,0,$E27*INDEX('ETF데이터'!$D$4:$D$594,$K27)) | G27: =IF($K27=0,0,$F27*INDEX('ETF데이터'!$J$4:$J$594,$K27)/12) | H27: =$G27*(1-$C$13*$O27) | K27: =IF($B27="",0,IFERROR(MATCH($B27,선택가능종목,0),0)) | L27: =IF($K27=0,"",INDEX('ETF데이터'!$M$4:$M$594,$K27)) | M27: =IF($K27=0,"",INDEX('ETF데이터'!$R$4:$R$594,$K27)) | N27: =IF(OR($M27="",$M27="월배당"),0,1) | O27: =IF($K27=0,1,IF(INDEX('ETF데이터'!$T$4:$T$594,$K27)="",1,INDEX('ETF데이터'!$T$4:$T$594,$K27))) | P27: =IF($K27=0,0,IF(INDEX('ETF데이터'!$T$4:$T$594,$K27)="",1,0))
B28: =IF(담긴수=0,"",IFERROR(INDEX(담긴목록,9),"")) | C28: =IF($B28="","",IF($C$12="비율",IF(9<MAX(담긴수,1),ROUND(100/MAX(담긴수,1),2),100-ROUND(100/MAX(담긴수,1),2)*(MAX(담긴수,1)-1)),IF(9<MAX(담긴수,1),ROUNDDOWN($C$11/MAX(담긴수,1),0),$C$11-ROUNDDOWN($C$11/MAX(담긴수,1),0)*(MAX(담긴수,1)-1)))) | D28: =IF($K28=0,0,IF($C$12="비율",ROUND($C$11*$C28/100,0),$C28)) | E28: =IF($K28=0,0,ROUNDDOWN($D28/INDEX('ETF데이터'!$D$4:$D$594,$K28),0)) | F28: =IF($K28=0,0,$E28*INDEX('ETF데이터'!$D$4:$D$594,$K28)) | G28: =IF($K28=0,0,$F28*INDEX('ETF데이터'!$J$4:$J$594,$K28)/12) | H28: =$G28*(1-$C$13*$O28) | K28: =IF($B28="",0,IFERROR(MATCH($B28,선택가능종목,0),0)) | L28: =IF($K28=0,"",INDEX('ETF데이터'!$M$4:$M$594,$K28)) | M28: =IF($K28=0,"",INDEX('ETF데이터'!$R$4:$R$594,$K28)) | N28: =IF(OR($M28="",$M28="월배당"),0,1) | O28: =IF($K28=0,1,IF(INDEX('ETF데이터'!$T$4:$T$594,$K28)="",1,INDEX('ETF데이터'!$T$4:$T$594,$K28))) | P28: =IF($K28=0,0,IF(INDEX('ETF데이터'!$T$4:$T$594,$K28)="",1,0))
B29: =IF(담긴수=0,"",IFERROR(INDEX(담긴목록,10),"")) | C29: =IF($B29="","",IF($C$12="비율",IF(10<MAX(담긴수,1),ROUND(100/MAX(담긴수,1),2),100-ROUND(100/MAX(담긴수,1),2)*(MAX(담긴수,1)-1)),IF(10<MAX(담긴수,1),ROUNDDOWN($C$11/MAX(담긴수,1),0),$C$11-ROUNDDOWN($C$11/MAX(담긴수,1),0)*(MAX(담긴수,1)-1)))) | D29: =IF($K29=0,0,IF($C$12="비율",ROUND($C$11*$C29/100,0),$C29)) | E29: =IF($K29=0,0,ROUNDDOWN($D29/INDEX('ETF데이터'!$D$4:$D$594,$K29),0)) | F29: =IF($K29=0,0,$E29*INDEX('ETF데이터'!$D$4:$D$594,$K29)) | G29: =IF($K29=0,0,$F29*INDEX('ETF데이터'!$J$4:$J$594,$K29)/12) | H29: =$G29*(1-$C$13*$O29) | K29: =IF($B29="",0,IFERROR(MATCH($B29,선택가능종목,0),0)) | L29: =IF($K29=0,"",INDEX('ETF데이터'!$M$4:$M$594,$K29)) | M29: =IF($K29=0,"",INDEX('ETF데이터'!$R$4:$R$594,$K29)) | N29: =IF(OR($M29="",$M29="월배당"),0,1) | O29: =IF($K29=0,1,IF(INDEX('ETF데이터'!$T$4:$T$594,$K29)="",1,INDEX('ETF데이터'!$T$4:$T$594,$K29))) | P29: =IF($K29=0,0,IF(INDEX('ETF데이터'!$T$4:$T$594,$K29)="",1,0))
B30: 합계 | C30: =SUM(C20:C29) | D30: =SUM(D20:D29) | F30: =SUM(F20:F29) | G30: =SUM(G20:G29) | H30: =SUM(H20:H29)
B31: =IF($C$12="비율",IF(ABS($C30-100)>0.01,"※ 배분 비율 합계가 100%가 아닙니다. 배분 칸을 확인하십시오.",""),IF($D30>$C$11,"※ 배분 금액 합계가 총 투자금액을 넘습니다.",""))
B32: =IF(COUNTIF($L$20:$L$29,"제외")>0,"※ 유동성·변동성 기준에 미달한 종목이 담겨 있습니다. [ETF데이터] 장의 제외 사유를 확인하십시오.","")
B33: =IF(SUM($N$20:$N$29)>0,"※ 월배당이 아닌 종목이 담겨 있습니다. 위의 '월 예상 분배금' 은 연 분배금을 12로 나눈 월 환산액이며, 실제 지급은 그 종목의 주기(분기·연 등)를 따릅니다.","")
B34: =IF(SUM($P$20:$P$29)>0,"※ 과세표준을 확인하지 못한 종목이 담겨 있습니다. 그 종목은 분배금 전액에 세율을 적용해 계산했으므로, 실제 세후 수령액은 표시된 금액보다 많을 수 있습니다.","")
B35: 빈 줄은 계산에서 빠집니다. 한 종목만 담으려면 첫 줄에만 넣고 배분을 100 으로 두십시오.
A38: 3 | B38: 예상 분배금 요약
B40: 총 투자금액 | C40: =$C$11 | F40: 월 예상 분배금 (세전) | G40: =$G$30
B41: 실제 투자금액 | C41: =$F$30 | F41: 월 예상 분배금 (세후) | G41: =$H$30
B42: 미투자 잔액 | C42: =$C$11-$F$30 | F42: 연 예상 분배금 (세전) | G42: =$G$30*12
B43: 담은 종목 수 | C43: =COUNTIF($K$20:$K$29,">0") | F43: 연 예상 분배금 (세후) | G43: =$H$30*12
B44: 연 수익률 (세전, 가중평균) | C44: =IF($F$30=0,0,$G$30*12/$F$30) | F44: 월 수익률 (세전) | G44: =IF($F$30=0,0,$G$30/$F$30)
B45: 연 수익률 (세후, 가중평균) | C45: =IF($F$30=0,0,$H$30*12/$F$30) | F45: 월 수익률 (세후) | G45: =IF($F$30=0,0,$H$30/$F$30)
B46: 연 수익률은 담은 종목들의 최근 12개월 실제 분배금을 투자 비중으로 가중한 값입니다. 확정 수익률이 아니며 매월 달라집니다.
A49: 4 | B49: 총 투자금액별 예상 분배금 (위 구성을 그대로 두고 금액만 바꿨을 때)
B51: 투자금액 구간 | C51: 월 분배금(세전) | D51: 월 분배금(세후) | E51: 연 분배금(세전) | F51: 연 분배금(세후)
B52: 10000000 | C52: =$B52*$C$44/12 | D52: =$C52*IF($G$30=0,1-$C$13,$H$30/$G$30) | E52: =$B52*$C$44 | F52: =$E52*IF($G$30=0,1-$C$13,$H$30/$G$30)
B53: 30000000 | C53: =$B53*$C$44/12 | D53: =$C53*IF($G$30=0,1-$C$13,$H$30/$G$30) | E53: =$B53*$C$44 | F53: =$E53*IF($G$30=0,1-$C$13,$H$30/$G$30)
...

Sheet 종목조회
A1: 사내한 · Confidential
A2: ETF 종목 조회
A3: ETF Screener
A5: 자료 ETFCHECK · 기준일 2026-10-02 · 지급주기와 연 분배율로 고릅니다
A8: 1 | B8: 조회 조건
B10: 지급주기 | C10: 전체 | E10: 분배율은 백분율로 넣으십시오 (예: 5%). 최소·최대 사이에 드는 종목만 나옵니다.
B11: 연 분배율 최소 | C11: 0 | E11: '판정 불가' 는 상장 1년이 안 돼 주기를 말할 수 없는 종목입니다. 빼지 않고 그대로 담았습니다.
B12: 연 분배율 최대 | C12: 1 | E12: 결과는 기준을 통과한 종목이 먼저, 그 안에서 연 분배율 높은 순입니다.
B14: 조건에 맞는 종목 | C14: =COUNTIF('ETF데이터'!$AA$4:$AA$594,1) | D14: 전체 591종목 중
A17: 2 | B17: 조회 결과 (최대 60종목)
B19: 종목명 | C19: 지급주기 | D19: 연 분배율 | E19: 월 환산 | F19: 현재가 | G19: 변동성 | H19: 순자산 | I19: 총수익 1년 | J19: 기준가 1년 | K19: 기준가 6개월 | L19: 기준가 3개월 | M19: 채택 | N19: 담기
B20: =IF($O20=0,"",INDEX('ETF데이터'!$A$4:$A$594,$O20)) | C20: =IF($O20=0,"",INDEX('ETF데이터'!$R$4:$R$594,$O20)) | D20: =IF($O20=0,"",INDEX('ETF데이터'!$J$4:$J$594,$O20)) | E20: =IF($O20=0,"",$D20/12) | F20: =IF($O20=0,"",INDEX('ETF데이터'!$D$4:$D$594,$O20)) | G20: =IF($O20=0,"",INDEX('ETF데이터'!$H$4:$H$594,$O20)) | H20: =IF($O20=0,"",INDEX('ETF데이터'!$E$4:$E$594,$O20)/100000000) | I20: =IF($O20=0,"",IF(INDEX('ETF데이터'!$U$4:$U$594,$O20)="","",INDEX('ETF데이터'!$U$4:$U$594,$O20))) | J20: =IF($O20=0,"",IF(INDEX('ETF데이터'!$V$4:$V$594,$O20)="","",INDEX('ETF데이터'!$V$4:$V$594,$O20))) | K20: =IF($O20=0,"",IF(INDEX('ETF데이터'!$W$4:$W$594,$O20)="","",INDEX('ETF데이터'!$W$4:$W$594,$O20))) | L20: =IF($O20=0,"",IF(INDEX('ETF데이터'!$X$4:$X$594,$O20)="","",INDEX('ETF데이터'!$X$4:$X$594,$O20))) | M20: =IF($O20=0,"",INDEX('ETF데이터'!$M$4:$M$594,$O20)) | O20: =IFERROR(MATCH(1,'ETF데이터'!$AB$4:$AB$594,0),0) | P20: =IF(AND($B20<>"",$N20<>""),1,0) | Q20: =IF($P20=1,0+1,0) | R20: =IFERROR(INDEX($B$20:$B$79,MATCH(1,$Q$20:$Q$79,0)),"")
B21: =IF($O21=0,"",INDEX('ETF데이터'!$A$4:$A$594,$O21)) | C21: =IF($O21=0,"",INDEX('ETF데이터'!$R$4:$R$594,$O21)) | D21: =IF($O21=0,"",INDEX('ETF데이터'!$J$4:$J$594,$O21)) | E21: =IF($O21=0,"",$D21/12) | F21: =IF($O21=0,"",INDEX('ETF데이터'!$D$4:$D$594,$O21)) | G21: =IF($O21=0,"",INDEX('ETF데이터'!$H$4:$H$594,$O21)) | H21: =IF($O21=0,"",INDEX('ETF데이터'!$E$4:$E$594,$O21)/100000000) | I21: =IF($O21=0,"",IF(INDEX('ETF데이터'!$U$4:$U$594,$O21)="","",INDEX('ETF데이터'!$U$4:$U$594,$O21))) | J21: =IF($O21=0,"",IF(INDEX('ETF데이터'!$V$4:$V$594,$O21)="","",INDEX('ETF데이터'!$V$4:$V$594,$O21))) | K21: =IF($O21=0,"",IF(INDEX('ETF데이터'!$W$4:$W$594,$O21)="","",INDEX('ETF데이터'!$W$4:$W$594,$O21))) | L21: =IF($O21=0,"",IF(INDEX('ETF데이터'!$X$4:$X$594,$O21)="","",INDEX('ETF데이터'!$X$4:$X$594,$O21))) | M21: =IF($O21=0,"",INDEX('ETF데이터'!$M$4:$M$594,$O21)) | O21: =IFERROR(MATCH(2,'ETF데이터'!$AB$4:$AB$594,0),0) | P21: =IF(AND($B21<>"",$N21<>""),1,0) | Q21: =IF($P21=1,$Q20+1,$Q20) | R21: =IFERROR(INDEX($B$20:$B$79,MATCH(2,$Q$20:$Q$79,0)),"")
B22: =IF($O22=0,"",INDEX('ETF데이터'!$A$4:$A$594,$O22)) | C22: =IF($O22=0,"",INDEX('ETF데이터'!$R$4:$R$594,$O22)) | D22: =IF($O22=0,"",INDEX('ETF데이터'!$J$4:$J$594,$O22)) | E22: =IF($O22=0,"",$D22/12) | F22: =IF($O22=0,"",INDEX('ETF데이터'!$D$4:$D$594,$O22)) | G22: =IF($O22=0,"",INDEX('ETF데이터'!$H$4:$H$594,$O22)) | H22: =IF($O22=0,"",INDEX('ETF데이터'!$E$4:$E$594,$O22)/100000000) | I22: =IF($O22=0,"",IF(INDEX('ETF데이터'!$U$4:$U$594,$O22)="","",INDEX('ETF데이터'!$U$4:$U$594,$O22))) | J22: =IF($O22=0,"",IF(INDEX('ETF데이터'!$V$4:$V$594,$O22)="","",INDEX('ETF데이터'!$V$4:$V$594,$O22))) | K22: =IF($O22=0,"",IF(INDEX('ETF데이터'!$W$4:$W$594,$O22)="","",INDEX('ETF데이터'!$W$4:$W$594,$O22))) | L22: =IF($O22=0,"",IF(INDEX('ETF데이터'!$X$4:$X$594,$O22)="","",INDEX('ETF데이터'!$X$4:$X$594,$O22))) | M22: =IF($O22=0,"",INDEX('ETF데이터'!$M$4:$M$594,$O22)) | O22: =IFERROR(MATCH(3,'ETF데이터'!$AB$4:$AB$594,0),0) | P22: =IF(AND($B22<>"",$N22<>""),1,0) | Q22: =IF($P22=1,$Q21+1,$Q21) | R22: =IFERROR(INDEX($B$20:$B$79,MATCH(3,$Q$20:$Q$79,0)),"")
B23: =IF($O23=0,"",INDEX('ETF데이터'!$A$4:$A$594,$O23)) | C23: =IF($O23=0,"",INDEX('ETF데이터'!$R$4:$R$594,$O23)) | D23: =IF($O23=0,"",INDEX('ETF데이터'!$J$4:$J$594,$O23)) | E23: =IF($O23=0,"",$D23/12) | F23: =IF($O23=0,"",INDEX('ETF데이터'!$D$4:$D$594,$O23)) | G23: =IF($O23=0,"",INDEX('ETF데이터'!$H$4:$H$594,$O23)) | H23: =IF($O23=0,"",INDEX('ETF데이터'!$E$4:$E$594,$O23)/100000000) | I23: =IF($O23=0,"",IF(INDEX('ETF데이터'!$U$4:$U$594,$O23)="","",INDEX('ETF데이터'!$U$4:$U$594,$O23))) | J23: =IF($O23=0,"",IF(INDEX('ETF데이터'!$V$4:$V$594,$O23)="","",INDEX('ETF데이터'!$V$4:$V$594,$O23))) | K23: =IF($O23=0,"",IF(INDEX('ETF데이터'!$W$4:$W$594,$O23)="","",INDEX('ETF데이터'!$W$4:$W$594,$O23))) | L23: =IF($O23=0,"",IF(INDEX('ETF데이터'!$X$4:$X$594,$O23)="","",INDEX('ETF데이터'!$X$4:$X$594,$O23))) | M23: =IF($O23=0,"",INDEX('ETF데이터'!$M$4:$M$594,$O23)) | O23: =IFERROR(MATCH(4,'ETF데이터'!$AB$4:$AB$594,0),0) | P23: =IF(AND($B23<>"",$N23<>""),1,0) | Q23: =IF($P23=1,$Q22+1,$Q22) | R23: =IFERROR(INDEX($B$20:$B$79,MATCH(4,$Q$20:$Q$79,0)),"")
B24: =IF($O24=0,"",INDEX('ETF데이터'!$A$4:$A$594,$O24)) | C24: =IF($O24=0,"",INDEX('ETF데이터'!$R$4:$R$594,$O24)) | D24: =IF($O24=0,"",INDEX('ETF데이터'!$J$4:$J$594,$O24)) | E24: =IF($O24=0,"",$D24/12) | F24: =IF($O24=0,"",INDEX('ETF데이터'!$D$4:$D$594,$O24)) | G24: =IF($O24=0,"",INDEX('ETF데이터'!$H$4:$H$594,$O24)) | H24: =IF($O24=0,"",INDEX('ETF데이터'!$E$4:$E$594,$O24)/100000000) | I24: =IF($O24=0,"",IF(INDEX('ETF데이터'!$U$4:$U$594,$O24)="","",INDEX('ETF데이터'!$U$4:$U$594,$O24))) | J24: =IF($O24=0,"",IF(INDEX('ETF데이터'!$V$4:$V$594,$O24)="","",INDEX('ETF데이터'!$V$4:$V$594,$O24))) | K24: =IF($O24=0,"",IF(INDEX('ETF데이터'!$W$4:$W$594,$O24)="","",INDEX('ETF데이터'!$W$4:$W$594,$O24))) | L24: =IF($O24=0,"",IF(INDEX('ETF데이터'!$X$4:$X$594,$O24)="","",INDEX('ETF데이터'!$X$4:$X$594,$O24))) | M24: =IF($O24=0,"",INDEX('ETF데이터'!$M$4:$M$594,$O24)) | O24: =IFERROR(MATCH(5,'ETF데이터'!$AB$4:$AB$594,0),0) | P24: =IF(AND($B24<>"",$N24<>""),1,0) | Q24: =IF($P24=1,$Q23+1,$Q23) | R24: =IFERROR(INDEX($B$20:$B$79,MATCH(5,$Q$20:$Q$79,0)),"")
B25: =IF($O25=0,"",INDEX('ETF데이터'!$A$4:$A$594,$O25)) | C25: =IF($O25=0,"",INDEX('ETF데이터'!$R$4:$R$594,$O25)) | D25: =IF($O25=0,"",INDEX('ETF데이터'!$J$4:$J$594,$O25)) | E25: =IF($O25=0,"",$D25/12) | F25: =IF($O25=0,"",INDEX('ETF데이터'!$D$4:$D$594,$O25)) | G25: =IF($O25=0,"",INDEX('ETF데이터'!$H$4:$H$594,$O25)) | H25: =IF($O25=0,"",INDEX('ETF데이터'!$E$4:$E$594,$O25)/100000000) | I25: =IF($O25=0,"",IF(INDEX('ETF데이터'!$U$4:$U$594,$O25)="","",INDEX('ETF데이터'!$U$4:$U$594,$O25))) | J25: =IF($O25=0,"",IF(INDEX('ETF데이터'!$V$4:$V$594,$O25)="","",INDEX('ETF데이터'!$V$4:$V$594,$O25))) | K25: =IF($O25=0,"",IF(INDEX('ETF데이터'!$W$4:$W$594,$O25)="","",INDEX('ETF데이터'!$W$4:$W$594,$O25))) | L25: =IF($O25=0,"",IF(INDEX('ETF데이터'!$X$4:$X$594,$O25)="","",INDEX('ETF데이터'!$X$4:$X$594,$O25))) | M25: =IF($O25=0,"",INDEX('ETF데이터'!$M$4:$M$594,$O25)) | O25: =IFERROR(MATCH(6,'ETF데이터'!$AB$4:$AB$594,0),0) | P25: =IF(AND($B25<>"",$N25<>""),1,0) | Q25: =IF($P25=1,$Q24+1,$Q24) | R25: =IFERROR(INDEX($B$20:$B$79,MATCH(6,$Q$20:$Q$79,0)),"")
B26: =IF($O26=0,"",INDEX('ETF데이터'!$A$4:$A$594,$O26)) | C26: =IF($O26=0,"",INDEX('ETF데이터'!$R$4:$R$594,$O26)) | D26: =IF($O26=0,"",INDEX('ETF데이터'!$J$4:$J$594,$O26)) | E26: =IF($O26=0,"",$D26/12) | F26: =IF($O26=0,"",INDEX('ETF데이터'!$D$4:$D$594,$O26)) | G26: =IF($O26=0,"",INDEX('ETF데이터'!$H$4:$H$594,$O26)) | H26: =IF($O26=0,"",INDEX('ETF데이터'!$E$4:$E$594,$O26)/100000000) | I26: =IF($O26=0,"",IF(INDEX('ETF데이터'!$U$4:$U$594,$O26)="","",INDEX('ETF데이터'!$U$4:$U$594,$O26))) | J26: =IF($O26=0,"",IF(INDEX('ETF데이터'!$V$4:$V$594,$O26)="","",INDEX('ETF데이터'!$V$4:$V$594,$O26))) | K26: =IF($O26=0,"",IF(INDEX('ETF데이터'!$W$4:$W$594,$O26)="","",INDEX('ETF데이터'!$W$4:$W$594,$O26))) | L26: =IF($O26=0,"",IF(INDEX('ETF데이터'!$X$4:$X$594,$O26)="","",INDEX('ETF데이터'!$X$4:$X$594,$O26))) | M26: =IF($O26=0,"",INDEX('ETF데이터'!$M$4:$M$594,$O26)) | O26: =IFERROR(MATCH(7,'ETF데이터'!$AB$4:$AB$594,0),0) | P26: =IF(AND($B26<>"",$N26<>""),1,0) | Q26: =IF($P26=1,$Q25+1,$Q25) | R26: =IFERROR(INDEX($B$20:$B$79,MATCH(7,$Q$20:$Q$79,0)),"")
B27: =IF($O27=0,"",INDEX('ETF데이터'!$A$4:$A$594,$O27)) | C27: =IF($O27=0,"",INDEX('ETF데이터'!$R$4:$R$594,$O27)) | D27: =IF($O27=0,"",INDEX('ETF데이터'!$J$4:$J$594,$O27)) | E27: =IF($O27=0,"",$D27/12) | F27: =IF($O27=0,"",INDEX('ETF데이터'!$D$4:$D$594,$O27)) | G27: =IF($O27=0,"",INDEX('ETF데이터'!$H$4:$H$594,$O27)) | H27: =IF($O27=0,"",INDEX('ETF데이터'!$E$4:$E$594,$O27)/100000000) | I27: =IF($O27=0,"",IF(INDEX('ETF데이터'!$U$4:$U$594,$O27)="","",INDEX('ETF데이터'!$U$4:$U$594,$O27))) | J27: =IF($O27=0,"",IF(INDEX('ETF데이터'!$V$4:$V$594,$O27)="","",INDEX('ETF데이터'!$V$4:$V$594,$O27))) | K27: =IF($O27=0,"",IF(INDEX('ETF데이터'!$W$4:$W$594,$O27)="","",INDEX('ETF데이터'!$W$4:$W$594,$O27))) | L27: =IF($O27=0,"",IF(INDEX('ETF데이터'!$X$4:$X$594,$O27)="","",INDEX('ETF데이터'!$X$4:$X$594,$O27))) | M27: =IF($O27=0,"",INDEX('ETF데이터'!$M$4:$M$594,$O27)) | O27: =IFERROR(MATCH(8,'ETF데이터'!$AB$4:$AB$594,0),0) | P27: =IF(AND($B27<>"",$N27<>""),1,0) | Q27: =IF($P27=1,$Q26+1,$Q26) | R27: =IFERROR(INDEX($B$20:$B$79,MATCH(8,$Q$20:$Q$79,0)),"")
B28: =IF($O28=0,"",INDEX('ETF데이터'!$A$4:$A$594,$O28)) | C28: =IF($O28=0,"",INDEX('ETF데이터'!$R$4:$R$594,$O28)) | D28: =IF($O28=0,"",INDEX('ETF데이터'!$J$4:$J$594,$O28)) | E28: =IF($O28=0,"",$D28/12) | F28: =IF($O28=0,"",INDEX('ETF데이터'!$D$4:$D$594,$O28)) | G28: =IF($O28=0,"",INDEX('ETF데이터'!$H$4:$H$594,$O28)) | H28: =IF($O28=0,"",INDEX('ETF데이터'!$E$4:$E$594,$O28)/100000000) | I28: =IF($O28=0,"",IF(INDEX('ETF데이터'!$U$4:$U$594,$O28)="","",INDEX('ETF데이터'!$U$4:$U$594,$O28))) | J28: =IF($O28=0,"",IF(INDEX('ETF데이터'!$V$4:$V$594,$O28)="","",INDEX('ETF데이터'!$V$4:$V$594,$O28))) | K28: =IF($O28=0,"",IF(INDEX('ETF데이터'!$W$4:$W$594,$O28)="","",INDEX('ETF데이터'!$W$4:$W$594,$O28))) | L28: =IF($O28=0,"",IF(INDEX('ETF데이터'!$X$4:$X$594,$O28)="","",INDEX('ETF데이터'!$X$4:$X$594,$O28))) | M28: =IF($O28=0,"",INDEX('ETF데이터'!$M$4:$M$594,$O28)) | O28: =IFERROR(MATCH(9,'ETF데이터'!$AB$4:$AB$594,0),0) | P28: =IF(AND($B28<>"",$N28<>""),1,0) | Q28: =IF($P28=1,$Q27+1,$Q27) | R28: =IFERROR(INDEX($B$20:$B$79,MATCH(9,$Q$20:$Q$79,0)),"")
B29: =IF($O29=0,"",INDEX('ETF데이터'!$A$4:$A$594,$O29)) | C29: =IF($O29=0,"",INDEX('ETF데이터'!$R$4:$R$594,$O29)) | D29: =IF($O29=0,"",INDEX('ETF데이터'!$J$4:$J$594,$O29)) | E29: =IF($O29=0,"",$D29/12) | F29: =IF($O29=0,"",INDEX('ETF데이터'!$D$4:$D$594,$O29)) | G29: =IF($O29=0,"",INDEX('ETF데이터'!$H$4:$H$594,$O29)) | H29: =IF($O29=0,"",INDEX('ETF데이터'!$E$4:$E$594,$O29)/100000000) | I29: =IF($O29=0,"",IF(INDEX('ETF데이터'!$U$4:$U$594,$O29)="","",INDEX('ETF데이터'!$U$4:$U$594,$O29))) | J29: =IF($O29=0,"",IF(INDEX('ETF데이터'!$V$4:$V$594,$O29)="","",INDEX('ETF데이터'!$V$4:$V$594,$O29))) | K29: =IF($O29=0,"",IF(INDEX('ETF데이터'!$W$4:$W$594,$O29)="","",INDEX('ETF데이터'!$W$4:$W$594,$O29))) | L29: =IF($O29=0,"",IF(INDEX('ETF데이터'!$X$4:$X$594,$O29)="","",INDEX('ETF데이터'!$X$4:$X$594,$O29))) | M29: =IF($O29=0,"",INDEX('ETF데이터'!$M$4:$M$594,$O29)) | O29: =IFERROR(MATCH(10,'ETF데이터'!$AB$4:$AB$594,0),0) | P29: =IF(AND($B29<>"",$N29<>""),1,0) | Q29: =IF($P29=1,$Q28+1,$Q28) | R29: =IFERROR(INDEX($B$20:$B$79,MATCH(10,$Q$20:$Q$79,0)),"")
B30: =IF($O30=0,"",INDEX('ETF데이터'!$A$4:$A$594,$O30)) | C30: =IF($O30=0,"",INDEX('ETF데이터'!$R$4:$R$594,$O30)) | D30: =IF($O30=0,"",INDEX('ETF데이터'!$J$4:$J$594,$O30)) | E30: =IF($O30=0,"",$D30/12) | F30: =IF($O30=0,"",INDEX('ETF데이터'!$D$4:$D$594,$O30)) | G30: =IF($O30=0,"",INDEX('ETF데이터'!$H$4:$H$594,$O30)) | H30: =IF($O30=0,"",INDEX('ETF데이터'!$E$4:$E$594,$O30)/100000000) | I30: =IF($O30=0,"",IF(INDEX('ETF데이터'!$U$4:$U$594,$O30)="","",INDEX('ETF데이터'!$U$4:$U$594,$O30))) | J30: =IF($O30=0,"",IF(INDEX('ETF데이터'!$V$4:$V$594,$O30)="","",INDEX('ETF데이터'!$V$4:$V$594,$O30))) | K30: =IF($O30=0,"",IF(INDEX('ETF데이터'!$W$4:$W$594,$O30)="","",INDEX('ETF데이터'!$W$4:$W$594,$O30))) | L30: =IF($O30=0,"",IF(INDEX('ETF데이터'!$X$4:$X$594,$O30)="","",INDEX('ETF데이터'!$X$4:$X$594,$O30))) | M30: =IF($O30=0,"",INDEX('ETF데이터'!$M$4:$M$594,$O30)) | O30: =IFERROR(MATCH(11,'ETF데이터'!$AB$4:$AB$594,0),0) | P30: =IF(AND($B30<>"",$N30<>""),1,0) | Q30: =IF($P30=1,$Q29+1,$Q29) | R30: =IFERROR(INDEX($B$20:$B$79,MATCH(11,$Q$20:$Q$79,0)),"")
B31: =IF($O31=0,"",INDEX('ETF데이터'!$A$4:$A$594,$O31)) | C31: =IF($O31=0,"",INDEX('ETF데이터'!$R$4:$R$594,$O31)) | D31: =IF($O31=0,"",INDEX('ETF데이터'!$J$4:$J$594,$O31)) | E31: =IF($O31=0,"",$D31/12) | F31: =IF($O31=0,"",INDEX('ETF데이터'!$D$4:$D$594,$O31)) | G31: =IF($O31=0,"",INDEX('ETF데이터'!$H$4:$H$594,$O31)) | H31: =IF($O31=0,"",INDEX('ETF데이터'!$E$4:$E$594,$O31)/100000000) | I31: =IF($O31=0,"",IF(INDEX('ETF데이터'!$U$4:$U$594,$O31)="","",INDEX('ETF데이터'!$U$4:$U$594,$O31))) | J31: =IF($O31=0,"",IF(INDEX('ETF데이터'!$V$4:$V$594,$O31)="","",INDEX('ETF데이터'!$V$4:$V$594,$O31))) | K31: =IF($O31=0,"",IF(INDEX('ETF데이터'!$W$4:$W$594,$O31)="","",INDEX('ETF데이터'!$W$4:$W$594,$O31))) | L31: =IF($O31=0,"",IF(INDEX('ETF데이터'!$X$4:$X$594,$O31)="","",INDEX('ETF데이터'!$X$4:$X$594,$O31))) | M31: =IF($O31=0,"",INDEX('ETF데이터'!$M$4:$M$594,$O31)) | O31: =IFERROR(MATCH(12,'ETF데이터'!$AB$4:$AB$594,0),0) | P31: =IF(AND($B31<>"",$N31<>""),1,0) | Q31: =IF($P31=1,$Q30+1,$Q30) | R31: =IFERROR(INDEX($B$20:$B$79,MATCH(12,$Q$20:$Q$79,0)),"")
B32: =IF($O32=0,"",INDEX('ETF데이터'!$A$4:$A$594,$O32)) | C32: =IF($O32=0,"",INDEX('ETF데이터'!$R$4:$R$594,$O32)) | D32: =IF($O32=0,"",INDEX('ETF데이터'!$J$4:$J$594,$O32)) | E32: =IF($O32=0,"",$D32/12) | F32: =IF($O32=0,"",INDEX('ETF데이터'!$D$4:$D$594,$O32)) | G32: =IF($O32=0,"",INDEX('ETF데이터'!$H$4:$H$594,$O32)) | H32: =IF($O32=0,"",INDEX('ETF데이터'!$E$4:$E$594,$O32)/100000000) | I32: =IF($O32=0,"",IF(INDEX('ETF데이터'!$U$4:$U$594,$O32)="","",INDEX('ETF데이터'!$U$4:$U$594,$O32))) | J32: =IF($O32=0,"",IF(INDEX('ETF데이터'!$V$4:$V$594,$O32)="","",INDEX('ETF데이터'!$V$4:$V$594,$O32))) | K32: =IF($O32=0,"",IF(INDEX('ETF데이터'!$W$4:$W$594,$O32)="","",INDEX('ETF데이터'!$W$4:$W$594,$O32))) | L32: =IF($O32=0,"",IF(INDEX('ETF데이터'!$X$4:$X$594,$O32)="","",INDEX('ETF데이터'!$X$4:$X$594,$O32))) | M32: =IF($O32=0,"",INDEX('ETF데이터'!$M$4:$M$594,$O32)) | O32: =IFERROR(MATCH(13,'ETF데이터'!$AB$4:$AB$594,0),0) | P32: =IF(AND($B32<>"",$N32<>""),1,0) | Q32: =IF($P32=1,$Q31+1,$Q31) | R32: =IFERROR(INDEX($B$20:$B$79,MATCH(13,$Q$20:$Q$79,0)),"")
B33: =IF($O33=0,"",INDEX('ETF데이터'!$A$4:$A$594,$O33)) | C33: =IF($O33=0,"",INDEX('ETF데이터'!$R$4:$R$594,$O33)) | D33: =IF($O33=0,"",INDEX('ETF데이터'!$J$4:$J$594,$O33)) | E33: =IF($O33=0,"",$D33/12) | F33: =IF($O33=0,"",INDEX('ETF데이터'!$D$4:$D$594,$O33)) | G33: =IF($O33=0,"",INDEX('ETF데이터'!$H$4:$H$594,$O33)) | H33: =IF($O33=0,"",INDEX('ETF데이터'!$E$4:$E$594,$O33)/100000000) | I33: =IF($O33=0,"",IF(INDEX('ETF데이터'!$U$4:$U$594,$O33)="","",INDEX('ETF데이터'!$U$4:$U$594,$O33))) | J33: =IF($O33=0,"",IF(INDEX('ETF데이터'!$V$4:$V$594,$O33)="","",INDEX('ETF데이터'!$V$4:$V$594,$O33))) | K33: =IF($O33=0,"",IF(INDEX('ETF데이터'!$W$4:$W$594,$O33)="","",INDEX('ETF데이터'!$W$4:$W$594,$O33))) | L33: =IF($O33=0,"",IF(INDEX('ETF데이터'!$X$4:$X$594,$O33)="","",INDEX('ETF데이터'!$X$4:$X$594,$O33))) | M33: =IF($O33=0,"",INDEX('ETF데이터'!$M$4:$M$594,$O33)) | O33: =IFERROR(MATCH(14,'ETF데이터'!$AB$4:$AB$594,0),0) | P33: =IF(AND($B33<>"",$N33<>""),1,0) | Q33: =IF($P33=1,$Q32+1,$Q32) | R33: =IFERROR(INDEX($B$20:$B$79,MATCH(14,$Q$20:$Q$79,0)),"")
B34: =IF($O34=0,"",INDEX('ETF데이터'!$A$4:$A$594,$O34)) | C34: =IF($O34=0,"",INDEX('ETF데이터'!$R$4:$R$594,$O34)) | D34: =IF($O34=0,"",INDEX('ETF데이터'!$J$4:$J$594,$O34)) | E34: =IF($O34=0,"",$D34/12) | F34: =IF($O34=0,"",INDEX('ETF데이터'!$D$4:$D$594,$O34)) | G34: =IF($O34=0,"",INDEX('ETF데이터'!$H$4:$H$594,$O34)) | H34: =IF($O34=0,"",INDEX('ETF데이터'!$E$4:$E$594,$O34)/100000000) | I34: =IF($O34=0,"",IF(INDEX('ETF데이터'!$U$4:$U$594,$O34)="","",INDEX('ETF데이터'!$U$4:$U$594,$O34))) | J34: =IF($O34=0,"",IF(INDEX('ETF데이터'!$V$4:$V$594,$O34)="","",INDEX('ETF데이터'!$V$4:$V$594,$O34))) | K34: =IF($O34=0,"",IF(INDEX('ETF데이터'!$W$4:$W$594,$O34)="","",INDEX('ETF데이터'!$W$4:$W$594,$O34))) | L34: =IF($O34=0,"",IF(INDEX('ETF데이터'!$X$4:$X$594,$O34)="","",INDEX('ETF데이터'!$X$4:$X$594,$O34))) | M34: =IF($O34=0,"",INDEX('ETF데이터'!$M$4:$M$594,$O34)) | O34: =IFERROR(MATCH(15,'ETF데이터'!$AB$4:$AB$594,0),0) | P34: =IF(AND($B34<>"",$N34<>""),1,0) | Q34: =IF($P34=1,$Q33+1,$Q33) | R34: =IFERROR(INDEX($B$20:$B$79,MATCH(15,$Q$20:$Q$79,0)),"")
B35: =IF($O35=0,"",INDEX('ETF데이터'!$A$4:$A$594,$O35)) | C35: =IF($O35=0,"",INDEX('ETF데이터'!$R$4:$R$594,$O35)) | D35: =IF($O35=0,"",INDEX('ETF데이터'!$J$4:$J$594,$O35)) | E35: =IF($O35=0,"",$D35/12) | F35: =IF($O35=0,"",INDEX('ETF데이터'!$D$4:$D$594,$O35)) | G35: =IF($O35=0,"",INDEX('ETF데이터'!$H$4:$H$594,$O35)) | H35: =IF($O35=0,"",INDEX('ETF데이터'!$E$4:$E$594,$O35)/100000000) | I35: =IF($O35=0,"",IF(INDEX('ETF데이터'!$U$4:$U$594,$O35)="","",INDEX('ETF데이터'!$U$4:$U$594,$O35))) | J35: =IF($O35=0,"",IF(INDEX('ETF데이터'!$V$4:$V$594,$O35)="","",INDEX('ETF데이터'!$V$4:$V$594,$O35))) | K35: =IF($O35=0,"",IF(INDEX('ETF데이터'!$W$4:$W$594,$O35)="","",INDEX('ETF데이터'!$W$4:$W$594,$O35))) | L35: =IF($O35=0,"",IF(INDEX('ETF데이터'!$X$4:$X$594,$O35)="","",INDEX('ETF데이터'!$X$4:$X$594,$O35))) | M35: =IF($O35=0,"",INDEX('ETF데이터'!$M$4:$M$594,$O35)) | O35: =IFERROR(MATCH(16,'ETF데이터'!$AB$4:$AB$594,0),0) | P35: =IF(AND($B35<>"",$N35<>""),1,0) | Q35: =IF($P35=1,$Q34+1,$Q34) | R35: =IFERROR(INDEX($B$20:$B$79,MATCH(16,$Q$20:$Q$79,0)),"")
B36: =IF($O36=0,"",INDEX('ETF데이터'!$A$4:$A$594,$O36)) | C36: =IF($O36=0,"",INDEX('ETF데이터'!$R$4:$R$594,$O36)) | D36: =IF($O36=0,"",INDEX('ETF데이터'!$J$4:$J$594,$O36)) | E36: =IF($O36=0,"",$D36/12) | F36: =IF($O36=0,"",INDEX('ETF데이터'!$D$4:$D$594,$O36)) | G36: =IF($O36=0,"",INDEX('ETF데이터'!$H$4:$H$594,$O36)) | H36: =IF($O36=0,"",INDEX('ETF데이터'!$E$4:$E$594,$O36)/100000000) | I36: =IF($O36=0,"",IF(INDEX('ETF데이터'!$U$4:$U$594,$O36)="","",INDEX('ETF데이터'!$U$4:$U$594,$O36))) | J36: =IF($O36=0,"",IF(INDEX('ETF데이터'!$V$4:$V$594,$O36)="","",INDEX('ETF데이터'!$V$4:$V$594,$O36))) | K36: =IF($O36=0,"",IF(INDEX('ETF데이터'!$W$4:$W$594,$O36)="","",INDEX('ETF데이터'!$W$4:$W$594,$O36))) | L36: =IF($O36=0,"",IF(INDEX('ETF데이터'!$X$4:$X$594,$O36)="","",INDEX('ETF데이터'!$X$4:$X$594,$O36))) | M36: =IF($O36=0,"",INDEX('ETF데이터'!$M$4:$M$594,$O36)) | O36: =IFERROR(MATCH(17,'ETF데이터'!$AB$4:$AB$594,0),0) | P36: =IF(AND($B36<>"",$N36<>""),1,0) | Q36: =IF($P36=1,$Q35+1,$Q35) | R36: =IFERROR(INDEX($B$20:$B$79,MATCH(17,$Q$20:$Q$79,0)),"")
B37: =IF($O37=0,"",INDEX('ETF데이터'!$A$4:$A$594,$O37)) | C37: =IF($O37=0,"",INDEX('ETF데이터'!$R$4:$R$594,$O37)) | D37: =IF($O37=0,"",INDEX('ETF데이터'!$J$4:$J$594,$O37)) | E37: =IF($O37=0,"",$D37/12) | F37: =IF($O37=0,"",INDEX('ETF데이터'!$D$4:$D$594,$O37)) | G37: =IF($O37=0,"",INDEX('ETF데이터'!$H$4:$H$594,$O37)) | H37: =IF($O37=0,"",INDEX('ETF데이터'!$E$4:$E$594,$O37)/100000000) | I37: =IF($O37=0,"",IF(INDEX('ETF데이터'!$U$4:$U$594,$O37)="","",INDEX('ETF데이터'!$U$4:$U$594,$O37))) | J37: =IF($O37=0,"",IF(INDEX('ETF데이터'!$V$4:$V$594,$O37)="","",INDEX('ETF데이터'!$V$4:$V$594,$O37))) | K37: =IF($O37=0,"",IF(INDEX('ETF데이터'!$W$4:$W$594,$O37)="","",INDEX('ETF데이터'!$W$4:$W$594,$O37))) | L37: =IF($O37=0,"",IF(INDEX('ETF데이터'!$X$4:$X$594,$O37)="","",INDEX('ETF데이터'!$X$4:$X$594,$O37))) | M37: =IF($O37=0,"",INDEX('ETF데이터'!$M$4:$M$594,$O37)) | O37: =IFERROR(MATCH(18,'ETF데이터'!$AB$4:$AB$594,0),0) | P37: =IF(AND($B37<>"",$N37<>""),1,0) | Q37: =IF($P37=1,$Q36+1,$Q36) | R37: =IFERROR(INDEX($B$20:$B$79,MATCH(18,$Q$20:$Q$79,0)),"")
B38: =IF($O38=0,"",INDEX('ETF데이터'!$A$4:$A$594,$O38)) | C38: =IF($O38=0,"",INDEX('ETF데이터'!$R$4:$R$594,$O38)) | D38: =IF($O38=0,"",INDEX('ETF데이터'!$J$4:$J$594,$O38)) | E38: =IF($O38=0,"",$D38/12) | F38: =IF($O38=0,"",INDEX('ETF데이터'!$D$4:$D$594,$O38)) | G38: =IF($O38=0,"",INDEX('ETF데이터'!$H$4:$H$594,$O38)) | H38: =IF($O38=0,"",INDEX('ETF데이터'!$E$4:$E$594,$O38)/100000000) | I38: =IF($O38=0,"",IF(INDEX('ETF데이터'!$U$4:$U$594,$O38)="","",INDEX('ETF데이터'!$U$4:$U$594,$O38))) | J38: =IF($O38=0,"",IF(INDEX('ETF데이터'!$V$4:$V$594,$O38)="","",INDEX('ETF데이터'!$V$4:$V$594,$O38))) | K38: =IF($O38=0,"",IF(INDEX('ETF데이터'!$W$4:$W$594,$O38)="","",INDEX('ETF데이터'!$W$4:$W$594,$O38))) | L38: =IF($O38=0,"",IF(INDEX('ETF데이터'!$X$4:$X$594,$O38)="","",INDEX('ETF데이터'!$X$4:$X$594,$O38))) | M38: =IF($O38=0,"",INDEX('ETF데이터'!$M$4:$M$594,$O38)) | O38: =IFERROR(MATCH(19,'ETF데이터'!$AB$4:$AB$594,0),0) | P38: =IF(AND($B38<>"",$N38<>""),1,0) | Q38: =IF($P38=1,$Q37+1,$Q37) | R38: =IFERROR(INDEX($B$20:$B$79,MATCH(19,$Q$20:$Q$79,0)),"")
B39: =IF($O39=0,"",INDEX('ETF데이터'!$A$4:$A$594,$O39)) | C39: =IF($O39=0,"",INDEX('ETF데이터'!$R$4:$R$594,$O39)) | D39: =IF($O39=0,"",INDEX('ETF데이터'!$J$4:$J$594,$O39)) | E39: =IF($O39=0,"",$D39/12) | F39: =IF($O39=0,"",INDEX('ETF데이터'!$D$4:$D$594,$O39)) | G39: =IF($O39=0,"",INDEX('ETF데이터'!$H$4:$H$594,$O39)) | H39: =IF($O39=0,"",INDEX('ETF데이터'!$E$4:$E$594,$O39)/100000000) | I39: =IF($O39=0,"",IF(INDEX('ETF데이터'!$U$4:$U$594,$O39)="","",INDEX('ETF데이터'!$U$4:$U$594,$O39))) | J39: =IF($O39=0,"",IF(INDEX('ETF데이터'!$V$4:$V$594,$O39)="","",INDEX('ETF데이터'!$V$4:$V$594,$O39))) | K39: =IF($O39=0,"",IF(INDEX('ETF데이터'!$W$4:$W$594,$O39)="","",INDEX('ETF데이터'!$W$4:$W$594,$O39))) | L39: =IF($O39=0,"",IF(INDEX('ETF데이터'!$X$4:$X$594,$O39)="","",INDEX('ETF데이터'!$X$4:$X$594,$O39))) | M39: =IF($O39=0,"",INDEX('ETF데이터'!$M$4:$M$594,$O39)) | O39: =IFERROR(MATCH(20,'ETF데이터'!$AB$4:$AB$594,0),0) | P39: =IF(AND($B39<>"",$N39<>""),1,0) | Q39: =IF($P39=1,$Q38+1,$Q38) | R39: =IFERROR(INDEX($B$20:$B$79,MATCH(20,$Q$20:$Q$79,0)),"")
B40: =IF($O40=0,"",INDEX('ETF데이터'!$A$4:$A$594,$O40)) | C40: =IF($O40=0,"",INDEX('ETF데이터'!$R$4:$R$594,$O40)) | D40: =IF($O40=0,"",INDEX('ETF데이터'!$J$4:$J$594,$O40)) | E40: =IF($O40=0,"",$D40/12) | F40: =IF($O40=0,"",INDEX('ETF데이터'!$D$4:$D$594,$O40)) | G40: =IF($O40=0,"",INDEX('ETF데이터'!$H$4:$H$594,$O40)) | H40: =IF($O40=0,"",INDEX('ETF데이터'!$E$4:$E$594,$O40)/100000000) | I40: =IF($O40=0,"",IF(INDEX('ETF데이터'!$U$4:$U$594,$O40)="","",INDEX('ETF데이터'!$U$4:$U$594,$O40))) | J40: =IF($O40=0,"",IF(INDEX('ETF데이터'!$V$4:$V$594,$O40)="","",INDEX('ETF데이터'!$V$4:$V$594,$O40))) | K40: =IF($O40=0,"",IF(INDEX('ETF데이터'!$W$4:$W$594,$O40)="","",INDEX('ETF데이터'!$W$4:$W$594,$O40))) | L40: =IF($O40=0,"",IF(INDEX('ETF데이터'!$X$4:$X$594,$O40)="","",INDEX('ETF데이터'!$X$4:$X$594,$O40))) | M40: =IF($O40=0,"",INDEX('ETF데이터'!$M$4:$M$594,$O40)) | O40: =IFERROR(MATCH(21,'ETF데이터'!$AB$4:$AB$594,0),0) | P40: =IF(AND($B40<>"",$N40<>""),1,0) | Q40: =IF($P40=1,$Q39+1,$Q39) | R40: =IFERROR(INDEX($B$20:$B$79,MATCH(21,$Q$20:$Q$79,0)),"")
B41: =IF($O41=0,"",INDEX('ETF데이터'!$A$4:$A$594,$O41)) | C41: =IF($O41=0,"",INDEX('ETF데이터'!$R$4:$R$594,$O41)) | D41: =IF($O41=0,"",INDEX('ETF데이터'!$J$4:$J$594,$O41)) | E41: =IF($O41=0,"",$D41/12) | F41: =IF($O41=0,"",INDEX('ETF데이터'!$D$4:$D$594,$O41)) | G41: =IF($O41=0,"",INDEX('ETF데이터'!$H$4:$H$594,$O41)) | H41: =IF($O41=0,"",INDEX('ETF데이터'!$E$4:$E$594,$O41)/100000000) | I41: =IF($O41=0,"",IF(INDEX('ETF데이터'!$U$4:$U$594,$O41)="","",INDEX('ETF데이터'!$U$4:$U$594,$O41))) | J41: =IF($O41=0,"",IF(INDEX('ETF데이터'!$V$4:$V$594,$O41)="","",INDEX('ETF데이터'!$V$4:$V$594,$O41))) | K41: =IF($O41=0,"",IF(INDEX('ETF데이터'!$W$4:$W$594,$O41)="","",INDEX('ETF데이터'!$W$4:$W$594,$O41))) | L41: =IF($O41=0,"",IF(INDEX('ETF데이터'!$X$4:$X$594,$O41)="","",INDEX('ETF데이터'!$X$4:$X$594,$O41))) | M41: =IF($O41=0,"",INDEX('ETF데이터'!$M$4:$M$594,$O41)) | O41: =IFERROR(MATCH(22,'ETF데이터'!$AB$4:$AB$594,0),0) | P41: =IF(AND($B41<>"",$N41<>""),1,0) | Q41: =IF($P41=1,$Q40+1,$Q40) | R41: =IFERROR(INDEX($B$20:$B$79,MATCH(22,$Q$20:$Q$79,0)),"")
B42: =IF($O42=0,"",INDEX('ETF데이터'!$A$4:$A$594,$O42)) | C42: =IF($O42=0,"",INDEX('ETF데이터'!$R$4:$R$594,$O42)) | D42: =IF($O42=0,"",INDEX('ETF데이터'!$J$4:$J$594,$O42)) | E42: =IF($O42=0,"",$D42/12) | F42: =IF($O42=0,"",INDEX('ETF데이터'!$D$4:$D$594,$O42)) | G42: =IF($O42=0,"",INDEX('ETF데이터'!$H$4:$H$594,$O42)) | H42: =IF($O42=0,"",INDEX('ETF데이터'!$E$4:$E$594,$O42)/100000000) | I42: =IF($O42=0,"",IF(INDEX('ETF데이터'!$U$4:$U$594,$O42)="","",INDEX('ETF데이터'!$U$4:$U$594,$O42))) | J42: =IF($O42=0,"",IF(INDEX('ETF데이터'!$V$4:$V$594,$O42)="","",INDEX('ETF데이터'!$V$4:$V$594,$O42))) | K42: =IF($O42=0,"",IF(INDEX('ETF데이터'!$W$4:$W$594,$O42)="","",INDEX('ETF데이터'!$W$4:$W$594,$O42))) | L42: =IF($O42=0,"",IF(INDEX('ETF데이터'!$X$4:$X$594,$O42)="","",INDEX('ETF데이터'!$X$4:$X$594,$O42))) | M42: =IF($O42=0,"",INDEX('ETF데이터'!$M$4:$M$594,$O42)) | O42: =IFERROR(MATCH(23,'ETF데이터'!$AB$4:$AB$594,0),0) | P42: =IF(AND($B42<>"",$N42<>""),1,0) | Q42: =IF($P42=1,$Q41+1,$Q41) | R42: =IFERROR(INDEX($B$20:$B$79,MATCH(23,$Q$20:$Q$79,0)),"")
B43: =IF($O43=0,"",INDEX('ETF데이터'!$A$4:$A$594,$O43)) | C43: =IF($O43=0,"",INDEX('ETF데이터'!$R$4:$R$594,$O43)) | D43: =IF($O43=0,"",INDEX('ETF데이터'!$J$4:$J$594,$O43)) | E43: =IF($O43=0,"",$D43/12) | F43: =IF($O43=0,"",INDEX('ETF데이터'!$D$4:$D$594,$O43)) | G43: =IF($O43=0,"",INDEX('ETF데이터'!$H$4:$H$594,$O43)) | H43: =IF($O43=0,"",INDEX('ETF데이터'!$E$4:$E$594,$O43)/100000000) | I43: =IF($O43=0,"",IF(INDEX('ETF데이터'!$U$4:$U$594,$O43)="","",INDEX('ETF데이터'!$U$4:$U$594,$O43))) | J43: =IF($O43=0,"",IF(INDEX('ETF데이터'!$V$4:$V$594,$O43)="","",INDEX('ETF데이터'!$V$4:$V$594,$O43))) | K43: =IF($O43=0,"",IF(INDEX('ETF데이터'!$W$4:$W$594,$O43)="","",INDEX('ETF데이터'!$W$4:$W$594,$O43))) | L43: =IF($O43=0,"",IF(INDEX('ETF데이터'!$X$4:$X$594,$O43)="","",INDEX('ETF데이터'!$X$4:$X$594,$O43))) | M43: =IF($O43=0,"",INDEX('ETF데이터'!$M$4:$M$594,$O43)) | O43: =IFERROR(MATCH(24,'ETF데이터'!$AB$4:$AB$594,0),0) | P43: =IF(AND($B43<>"",$N43<>""),1,0) | Q43: =IF($P43=1,$Q42+1,$Q42) | R43: =IFERROR(INDEX($B$20:$B$79,MATCH(24,$Q$20:$Q$79,0)),"")
B44: =IF($O44=0,"",INDEX('ETF데이터'!$A$4:$A$594,$O44)) | C44: =IF($O44=0,"",INDEX('ETF데이터'!$R$4:$R$594,$O44)) | D44: =IF($O44=0,"",INDEX('ETF데이터'!$J$4:$J$594,$O44)) | E44: =IF($O44=0,"",$D44/12) | F44: =IF($O44=0,"",INDEX('ETF데이터'!$D$4:$D$594,$O44)) | G44: =IF($O44=0,"",INDEX('ETF데이터'!$H$4:$H$594,$O44)) | H44: =IF($O44=0,"",INDEX('ETF데이터'!$E$4:$E$594,$O44)/100000000) | I44: =IF($O44=0,"",IF(INDEX('ETF데이터'!$U$4:$U$594,$O44)="","",INDEX('ETF데이터'!$U$4:$U$594,$O44))) | J44: =IF($O44=0,"",IF(INDEX('ETF데이터'!$V$4:$V$594,$O44)="","",INDEX('ETF데이터'!$V$4:$V$594,$O44))) | K44: =IF($O44=0,"",IF(INDEX('ETF데이터'!$W$4:$W$594,$O44)="","",INDEX('ETF데이터'!$W$4:$W$594,$O44))) | L44: =IF($O44=0,"",IF(INDEX('ETF데이터'!$X$4:$X$594,$O44)="","",INDEX('ETF데이터'!$X$4:$X$594,$O44))) | M44: =IF($O44=0,"",INDEX('ETF데이터'!$M$4:$M$594,$O44)) | O44: =IFERROR(MATCH(25,'ETF데이터'!$AB$4:$AB$594,0),0) | P44: =IF(AND($B44<>"",$N44<>""),1,0) | Q44: =IF($P44=1,$Q43+1,$Q43) | R44: =IFERROR(INDEX($B$20:$B$79,MATCH(25,$Q$20:$Q$79,0)),"")
B45: =IF($O45=0,"",INDEX('ETF데이터'!$A$4:$A$594,$O45)) | C45: =IF($O45=0,"",INDEX('ETF데이터'!$R$4:$R$594,$O45)) | D45: =IF($O45=0,"",INDEX('ETF데이터'!$J$4:$J$594,$O45)) | E45: =IF($O45=0,"",$D45/12) | F45: =IF($O45=0,"",INDEX('ETF데이터'!$D$4:$D$594,$O45)) | G45: =IF($O45=0,"",INDEX('ETF데이터'!$H$4:$H$594,$O45)) | H45: =IF($O45=0,"",INDEX('ETF데이터'!$E$4:$E$594,$O45)/100000000) | I45: =IF($O45=0,"",IF(INDEX('ETF데이터'!$U$4:$U$594,$O45)="","",INDEX('ETF데이터'!$U$4:$U$594,$O45))) | J45: =IF($O45=0,"",IF(INDEX('ETF데이터'!$V$4:$V$594,$O45)="","",INDEX('ETF데이터'!$V$4:$V$594,$O45))) | K45: =IF($O45=0,"",IF(INDEX('ETF데이터'!$W$4:$W$594,$O45)="","",INDEX('ETF데이터'!$W$4:$W$594,$O45))) | L45: =IF($O45=0,"",IF(INDEX('ETF데이터'!$X$4:$X$594,$O45)="","",INDEX('ETF데이터'!$X$4:$X$594,$O45))) | M45: =IF($O45=0,"",INDEX('ETF데이터'!$M$4:$M$594,$O45)) | O45: =IFERROR(MATCH(26,'ETF데이터'!$AB$4:$AB$594,0),0) | P45: =IF(AND($B45<>"",$N45<>""),1,0) | Q45: =IF($P45=1,$Q44+1,$Q44) | R45: =IFERROR(INDEX($B$20:$B$79,MATCH(26,$Q$20:$Q$79,0)),"")
B46: =IF($O46=0,"",INDEX('ETF데이터'!$A$4:$A$594,$O46)) | C46: =IF($O46=0,"",INDEX('ETF데이터'!$R$4:$R$594,$O46)) | D46: =IF($O46=0,"",INDEX('ETF데이터'!$J$4:$J$594,$O46)) | E46: =IF($O46=0,"",$D46/12) | F46: =IF($O46=0,"",INDEX('ETF데이터'!$D$4:$D$594,$O46)) | G46: =IF($O46=0,"",INDEX('ETF데이터'!$H$4:$H$594,$O46)) | H46: =IF($O46=0,"",INDEX('ETF데이터'!$E$4:$E$594,$O46)/100000000) | I46: =IF($O46=0,"",IF(INDEX('ETF데이터'!$U$4:$U$594,$O46)="","",INDEX('ETF데이터'!$U$4:$U$594,$O46))) | J46: =IF($O46=0,"",IF(INDEX('ETF데이터'!$V$4:$V$594,$O46)="","",INDEX('ETF데이터'!$V$4:$V$594,$O46))) | K46: =IF($O46=0,"",IF(INDEX('ETF데이터'!$W$4:$W$594,$O46)="","",INDEX('ETF데이터'!$W$4:$W$594,$O46))) | L46: =IF($O46=0,"",IF(INDEX('ETF데이터'!$X$4:$X$594,$O46)="","",INDEX('ETF데이터'!$X$4:$X$594,$O46))) | M46: =IF($O46=0,"",INDEX('ETF데이터'!$M$4:$M$594,$O46)) | O46: =IFERROR(MATCH(27,'ETF데이터'!$AB$4:$AB$594,0),0) | P46: =IF(AND($B46<>"",$N46<>""),1,0) | Q46: =IF($P46=1,$Q45+1,$Q45) | R46: =IFERROR(INDEX($B$20:$B$79,MATCH(27,$Q$20:$Q$79,0)),"")
B47: =IF($O47=0,"",INDEX('ETF데이터'!$A$4:$A$594,$O47)) | C47: =IF($O47=0,"",INDEX('ETF데이터'!$R$4:$R$594,$O47)) | D47: =IF($O47=0,"",INDEX('ETF데이터'!$J$4:$J$594,$O47)) | E47: =IF($O47=0,"",$D47/12) | F47: =IF($O47=0,"",INDEX('ETF데이터'!$D$4:$D$594,$O47)) | G47: =IF($O47=0,"",INDEX('ETF데이터'!$H$4:$H$594,$O47)) | H47: =IF($O47=0,"",INDEX('ETF데이터'!$E$4:$E$594,$O47)/100000000) | I47: =IF($O47=0,"",IF(INDEX('ETF데이터'!$U$4:$U$594,$O47)="","",INDEX('ETF데이터'!$U$4:$U$594,$O47))) | J47: =IF($O47=0,"",IF(INDEX('ETF데이터'!$V$4:$V$594,$O47)="","",INDEX('ETF데이터'!$V$4:$V$594,$O47))) | K47: =IF($O47=0,"",IF(INDEX('ETF데이터'!$W$4:$W$594,$O47)="","",INDEX('ETF데이터'!$W$4:$W$594,$O47))) | L47: =IF($O47=0,"",IF(INDEX('ETF데이터'!$X$4:$X$594,$O47)="","",INDEX('ETF데이터'!$X$4:$X$594,$O47))) | M47: =IF($O47=0,"",INDEX('ETF데이터'!$M$4:$M$594,$O47)) | O47: =IFERROR(MATCH(28,'ETF데이터'!$AB$4:$AB$594,0),0) | P47: =IF(AND($B47<>"",$N47<>""),1,0) | Q47: =IF($P47=1,$Q46+1,$Q46) | R47: =IFERROR(INDEX($B$20:$B$79,MATCH(28,$Q$20:$Q$79,0)),"")
B48: =IF($O48=0,"",INDEX('ETF데이터'!$A$4:$A$594,$O48)) | C48: =IF($O48=0,"",INDEX('ETF데이터'!$R$4:$R$594,$O48)) | D48: =IF($O48=0,"",INDEX('ETF데이터'!$J$4:$J$594,$O48)) | E48: =IF($O48=0,"",$D48/12) | F48: =IF($O48=0,"",INDEX('ETF데이터'!$D$4:$D$594,$O48)) | G48: =IF($O48=0,"",INDEX('ETF데이터'!$H$4:$H$594,$O48)) | H48: =IF($O48=0,"",INDEX('ETF데이터'!$E$4:$E$594,$O48)/100000000) | I48: =IF($O48=0,"",IF(INDEX('ETF데이터'!$U$4:$U$594,$O48)="","",INDEX('ETF데이터'!$U$4:$U$594,$O48))) | J48: =IF($O48=0,"",IF(INDEX('ETF데이터'!$V$4:$V$594,$O48)="","",INDEX('ETF데이터'!$V$4:$V$594,$O48))) | K48: =IF($O48=0,"",IF(INDEX('ETF데이터'!$W$4:$W$594,$O48)="","",INDEX('ETF데이터'!$W$4:$W$594,$O48))) | L48: =IF($O48=0,"",IF(INDEX('ETF데이터'!$X$4:$X$594,$O48)="","",INDEX('ETF데이터'!$X$4:$X$594,$O48))) | M48: =IF($O48=0,"",INDEX('ETF데이터'!$M$4:$M$594,$O48)) | O48: =IFERROR(MATCH(29,'ETF데이터'!$AB$4:$AB$594,0),0) | P48: =IF(AND($B48<>"",$N48<>""),1,0) | Q48: =IF($P48=1,$Q47+1,$Q47) | R48: =IFERROR(INDEX($B$20:$B$79,MATCH(29,$Q$20:$Q$79,0)),"")
...

Sheet ETF데이터
A1: ETFCHECK 수집 원본 — 이 장의 값은 손으로 고치지 마십시오. 매월 1일 수집기가 덮어씁니다.
A3: 종목명 | B3: 종목코드 | C3: 운용사 | D3: 현재가 | E3: 순자산총액 | F3: 60일 평균거래대금 | G3: 총보수(연) | H3: 변동성(1년) | I3: 최근 월분배율 | J3: 연환산 분배율 | K3: 분배 기록수 | L3: 최근 분배기준일 | M3: 채택 | N3: 제외 사유 | O3: 기초지수 | P3: 유형 | Q3: 자산군 | R3: 지급주기 | S3: 연 지급횟수 | T3: 과세비율 | U3: 총수익 1년 | V3: 기준가 1년 | W3: 기준가 6개월 | X3: 기준가 3개월 | Y3: 수익률 창 | Z3: 수익률 비고
A4: SOL 팔란티어커버드콜OTM채권혼합 | B4: 0040Y0 | C4: 신한자산운용 | D4: 7885 | E4: 364287000000 | F4: 2676209983 | G4: 0.0035 | H4: 0.164 | I4: 0.0196 | J4: 0.277108 | K4: 17 | L4: 20260929 | M4: 채택 | O4: KEDI Palantir Covered Call OTM Treasury Balanced Index NTR | P4: 커버드콜 | Q4: 멀티에셋 | R4: 월배당 | S4: 11 | T4: 0.1904 | U4: -0.0197 | V4: -0.232 | W4: -0.1211 | X4: -0.0325 | Y4: 20250922~20261002 | AA4: =IF(AND($J4<>"",OR(조회_주기="전체",$R4=조회_주기),$J4>=조회_최소,$J4<=조회_최대),1,0) | AB4: =IF($AA4=1,0+1,0) | AC4: =IF(검색어="",1,IF(ISNUMBER(SEARCH(검색어,$A4)),1,0)) | AD4: =IF($AC4=1,0+1,0) | AE4: =IFERROR(INDEX($A$4:$A$594,MATCH(1,$AD$4:$AD$594,0)),"")
A5: SOL 팔란티어미국채커버드콜혼합 | B5: 0040X0 | C5: 신한자산운용 | D5: 9030 | E5: 169764000000 | F5: 1483144816 | G5: 0.0035 | H5: 0.2284 | I5: 0.015 | J5: 0.253156 | K5: 17 | L5: 20260929 | M5: 채택 | O5: KEDI Palantir U.S. Treasury Covered Call Balanced Index NTR | P5: 커버드콜 | Q5: 멀티에셋 | R5: 월배당 | S5: 11 | T5: 0.7183 | U5: -0.0343 | V5: -0.229 | W5: -0.1356 | X5: -0.0794 | Y5: 20250922~20261002 | AA5: =IF(AND($J5<>"",OR(조회_주기="전체",$R5=조회_주기),$J5>=조회_최소,$J5<=조회_최대),1,0) | AB5: =IF($AA5=1,$AB4+1,$AB4) | AC5: =IF(검색어="",1,IF(ISNUMBER(SEARCH(검색어,$A5)),1,0)) | AD5: =IF($AC5=1,$AD4+1,$AD4) | AE5: =IFERROR(INDEX($A$4:$A$594,MATCH(2,$AD$4:$AD$594,0)),"")
A6: PLUS 고배당주위클리커버드콜 | B6: 489030 | C6: 한화자산운용 | D6: 6175 | E6: 305662500000 | F6: 4260074463 | G6: 0.003 | H6: 0.3086 | I6: 0.0147 | J6: 0.237085 | K6: 26 | L6: 20260929 | M6: 채택 | O6: 코스피 고배당 위클리 콜매도 ATM 지수 | P6: 커버드콜 | Q6: 주식 | R6: 월배당 | S6: 11 | T6: 0.2179 | U6: -0.23 | V6: -0.3775 | W6: -0.2742 | X6: -0.023 | Y6: 20250922~20261002 | AA6: =IF(AND($J6<>"",OR(조회_주기="전체",$R6=조회_주기),$J6>=조회_최소,$J6<=조회_최대),1,0) | AB6: =IF($AA6=1,$AB5+1,$AB5) | AC6: =IF(검색어="",1,IF(ISNUMBER(SEARCH(검색어,$A6)),1,0)) | AD6: =IF($AC6=1,$AD5+1,$AD5) | AE6: =IFERROR(INDEX($A$4:$A$594,MATCH(3,$AD$4:$AD$594,0)),"")
A7: KODEX 미국나스닥100데일리커버드콜OTM | B7: 494300 | C7: 삼성자산운용(ETF) | D7: 8855 | E7: 1055516000000 | F7: 12188428828 | G7: 0.0025 | H7: 0.196 | I7: 0.0166 | J7: 0.226426 | K7: 23 | L7: 20260929 | M7: 채택 | O7: Nasdaq-100 Daily Covered Call 101 Index TR | P7: 커버드콜 | Q7: 주식 | R7: 월배당 | S7: 11 | T7: 0.784 | U7: 0.0872 | V7: -0.1141 | W7: -0.0781 | X7: -0.1575 | Y7: 20250922~20261002 | AA7: =IF(AND($J7<>"",OR(조회_주기="전체",$R7=조회_주기),$J7>=조회_최소,$J7<=조회_최대),1,0) | AB7: =IF($AA7=1,$AB6+1,$AB6) | AC7: =IF(검색어="",1,IF(ISNUMBER(SEARCH(검색어,$A7)),1,0)) | AD7: =IF($AC7=1,$AD6+1,$AD6) | AE7: =IFERROR(INDEX($A$4:$A$594,MATCH(4,$AD$4:$AD$594,0)),"")
A8: RISE 미국테크100데일리고정커버드콜 | B8: 491620 | C8: KB자산운용 | D8: 10415 | E8: 595217250000 | F8: 6738144363 | G8: 0.0025 | H8: 0.2035 | I8: 0.0126 | J8: 0.214402 | K8: 24 | L8: 20260929 | M8: 채택 | O8: KEDI U.S. Tech100 90% Participation + Daily Options Premium | P8: 커버드콜 | Q8: 주식 | R8: 월배당 | S8: 11 | T8: 1 | U8: 0.1623 | V8: -0.0436 | W8: 0.0187 | X8: -0.1107 | Y8: 20250922~20261002 | AA8: =IF(AND($J8<>"",OR(조회_주기="전체",$R8=조회_주기),$J8>=조회_최소,$J8<=조회_최대),1,0) | AB8: =IF($AA8=1,$AB7+1,$AB7) | AC8: =IF(검색어="",1,IF(ISNUMBER(SEARCH(검색어,$A8)),1,0)) | AD8: =IF($AC8=1,$AD7+1,$AD7) | AE8: =IFERROR(INDEX($A$4:$A$594,MATCH(5,$AD$4:$AD$594,0)),"")
A9: ACE 미국500데일리타겟커버드콜(합성) | B9: 480030 | C9: 한국투신운용(ETF) | D9: 9545 | E9: 160356000000 | F9: 1319106274 | G9: 0.0045 | H9: 0.151 | I9: 0.0199 | J9: 0.203562 | K9: 29 | L9: 20260914 | M9: 채택 | O9: Bloomberg US 500 Large Cap Premium(SPY) Decrement 15% Distri | P9: 커버드콜 | Q9: 주식 | R9: 월배당 | S9: 11 | T9: 0.9012 | U9: 0.0943 | V9: -0.0919 | W9: -0.101 | X9: -0.1637 | Y9: 20250922~20261002 | AA9: =IF(AND($J9<>"",OR(조회_주기="전체",$R9=조회_주기),$J9>=조회_최소,$J9<=조회_최대),1,0) | AB9: =IF($AA9=1,$AB8+1,$AB8) | AC9: =IF(검색어="",1,IF(ISNUMBER(SEARCH(검색어,$A9)),1,0)) | AD9: =IF($AC9=1,$AD8+1,$AD8) | AE9: =IFERROR(INDEX($A$4:$A$594,MATCH(6,$AD$4:$AD$594,0)),"")
A10: RISE 미국AI밸류체인데일리고정커버드콜 | B10: 490590 | C10: KB자산운용 | D10: 14405 | E10: 834049500000 | F10: 8968858264 | G10: 0.0025 | H10: 0.3256 | I10: 0.013 | J10: 0.201666 | K10: 24 | L10: 20260929 | M10: 채택 | O10: KEDI U.S. AI Value Chain 90% Participation + Daily Options P | P10: 커버드콜 | Q10: 주식 | R10: 월배당 | S10: 11 | T10: 1 | U10: 0.3198 | V10: 0.0974 | W10: 0.138 | X10: -0.0823 | Y10: 20250922~20261002 | AA10: =IF(AND($J10<>"",OR(조회_주기="전체",$R10=조회_주기),$J10>=조회_최소,$J10<=조회_최대),1,0) | AB10: =IF($AA10=1,$AB9+1,$AB9) | AC10: =IF(검색어="",1,IF(ISNUMBER(SEARCH(검색어,$A10)),1,0)) | AD10: =IF($AC10=1,$AD9+1,$AD9) | AE10: =IFERROR(INDEX($A$4:$A$594,MATCH(7,$AD$4:$AD$594,0)),"")
A11: PLUS 고배당주위클리고정커버드콜 | B11: 0018C0 | C11: 한화자산운용 | D11: 10360 | E11: 79254000000 | F11: 960251867 | G11: 0.003 | H11: 0.2676 | I11: 0.0124 | J11: 0.17249 | K11: 19 | L11: 20260914 | M11: 채택 | O11: 코스피 고배당 위클리 고정 커버드콜 지수 | P11: 커버드콜 | Q11: 주식 | R11: 월배당 | S11: 11 | T11: 0.2602 | U11: 0.0253 | V11: -0.1254 | W11: -0.1807 | X11: -0.0347 | Y11: 20250922~20261002 | AA11: =IF(AND($J11<>"",OR(조회_주기="전체",$R11=조회_주기),$J11>=조회_최소,$J11<=조회_최대),1,0) | AB11: =IF($AA11=1,$AB10+1,$AB10) | AC11: =IF(검색어="",1,IF(ISNUMBER(SEARCH(검색어,$A11)),1,0)) | AD11: =IF($AC11=1,$AD10+1,$AD10) | AE11: =IFERROR(INDEX($A$4:$A$594,MATCH(8,$AD$4:$AD$594,0)),"")
A12: KODEX 금융고배당TOP10타겟위클리커버드콜 | B12: 498410 | C12: 삼성자산운용(ETF) | D12: 11350 | E12: 850115000000 | F12: 20811303029 | G12: 0.0039 | H12: 0.3261 | I12: 0.0123 | J12: 0.164758 | K12: 21 | L12: 20260929 | M12: 채택 | O12: 코스피 200 금융 고배당 TOP 10 타겟 15% 분배 위클리 커버드콜 | P12: 커버드콜 | Q12: 주식 | R12: 월배당 | S12: 11 | T12: 0.2 | U12: 0.028 | V12: -0.1179 | W12: -0.0987 | X12: -0.0479 | Y12: 20250922~20261002 | AA12: =IF(AND($J12<>"",OR(조회_주기="전체",$R12=조회_주기),$J12>=조회_최소,$J12<=조회_최대),1,0) | AB12: =IF($AA12=1,$AB11+1,$AB11) | AC12: =IF(검색어="",1,IF(ISNUMBER(SEARCH(검색어,$A12)),1,0)) | AD12: =IF($AC12=1,$AD11+1,$AD11) | AE12: =IFERROR(INDEX($A$4:$A$594,MATCH(9,$AD$4:$AD$594,0)),"")
A13: KODEX 테슬라커버드콜채권혼합액티브 | B13: 475080 | C13: 삼성자산운용(ETF) | D13: 7770 | E13: 282439500000 | F13: 1211042513 | G13: 0.0039 | H13: 0.1246 | I13: 0.0124 | J13: 0.163707 | K13: 32 | L13: 20260929 | M13: 채택 | O13: KEDI Tesla Income Premium Balanced Index | P13: 커버드콜 | Q13: 멀티에셋 | R13: 월배당 | S13: 11 | T13: 0.4937 | U13: -0.014 | V13: -0.1534 | W13: -0.0816 | X13: -0.0831 | Y13: 20250922~20261002 | AA13: =IF(AND($J13<>"",OR(조회_주기="전체",$R13=조회_주기),$J13>=조회_최소,$J13<=조회_최대),1,0) | AB13: =IF($AA13=1,$AB12+1,$AB12) | AC13: =IF(검색어="",1,IF(ISNUMBER(SEARCH(검색어,$A13)),1,0)) | AD13: =IF($AC13=1,$AD12+1,$AD12) | AE13: =IFERROR(INDEX($A$4:$A$594,MATCH(10,$AD$4:$AD$594,0)),"")
A14: KODEX 미국S&P500데일리커버드콜OTM | B14: 0005A0 | C14: 삼성자산운용(ETF) | D14: 9050 | E14: 201815000000 | F14: 1966336033 | G14: 0.0025 | H14: 0.1485 | I14: 0.0128 | J14: 0.163646 | K14: 21 | L14: 20260929 | M14: 채택 | O14: S&P500 Covered Call 1% OTM Daily Index(TR) | P14: 커버드콜 | Q14: 주식 | R14: 월배당 | S14: 11 | T14: 0.921 | U14: 0.0987 | V14: -0.0562 | W14: -0.053 | X14: -0.1345 | Y14: 20250922~20261002 | AA14: =IF(AND($J14<>"",OR(조회_주기="전체",$R14=조회_주기),$J14>=조회_최소,$J14<=조회_최대),1,0) | AB14: =IF($AA14=1,$AB13+1,$AB13) | AC14: =IF(검색어="",1,IF(ISNUMBER(SEARCH(검색어,$A14)),1,0)) | AD14: =IF($AC14=1,$AD13+1,$AD13) | AE14: =IFERROR(INDEX($A$4:$A$594,MATCH(11,$AD$4:$AD$594,0)),"")
A15: TIGER 미국AI빅테크10타겟데일리커버드콜 | B15: 493810 | C15: 미래에셋자산운용 | D15: 11310 | E15: 238641000000 | F15: 1685432658 | G15: 0.0025 | H15: 0.2192 | I15: 0.0124 | J15: 0.160566 | K15: 23 | L15: 20260914 | M15: 채택 | O15: KEDI US AI Big Tech 10+15% Daily Premium Index TR | P15: 커버드콜 | Q15: 주식 | R15: 월배당 | S15: 11 | T15: 1 | U15: 0.1381 | V15: -0.0199 | W15: 0.0159 | X15: -0.0813 | Y15: 20250922~20261002 | AA15: =IF(AND($J15<>"",OR(조회_주기="전체",$R15=조회_주기),$J15>=조회_최소,$J15<=조회_최대),1,0) | AB15: =IF($AA15=1,$AB14+1,$AB14) | AC15: =IF(검색어="",1,IF(ISNUMBER(SEARCH(검색어,$A15)),1,0)) | AD15: =IF($AC15=1,$AD14+1,$AD14) | AE15: =IFERROR(INDEX($A$4:$A$594,MATCH(12,$AD$4:$AD$594,0)),"")
A16: KODEX 미국AI테크TOP10타겟커버드콜 | B16: 483280 | C16: 삼성자산운용(ETF) | D16: 11715 | E16: 461571000000 | F16: 2565746916 | G16: 0.0039 | H16: 0.2464 | I16: 0.0126 | J16: 0.156808 | K16: 28 | L16: 20260929 | M16: 채택 | O16: KEDI US AI Tech Top 10+15% Premium Index | P16: 커버드콜 | Q16: 주식 | R16: 월배당 | S16: 11 | T16: 1 | U16: 0.0959 | V16: -0.0533 | W16: 0.008 | X16: -0.0714 | Y16: 20250922~20261002 | AA16: =IF(AND($J16<>"",OR(조회_주기="전체",$R16=조회_주기),$J16>=조회_최소,$J16<=조회_최대),1,0) | AB16: =IF($AA16=1,$AB15+1,$AB15) | AC16: =IF(검색어="",1,IF(ISNUMBER(SEARCH(검색어,$A16)),1,0)) | AD16: =IF($AC16=1,$AD15+1,$AD15) | AE16: =IFERROR(INDEX($A$4:$A$594,MATCH(13,$AD$4:$AD$594,0)),"")
A17: TIGER 미국나스닥100타겟데일리커버드콜 | B17: 486290 | C17: 미래에셋자산운용 | D17: 10505 | E17: 2627300500000 | F17: 25774494369 | G17: 0.0025 | H17: 0.2085 | I17: 0.0126 | J17: 0.156307 | K17: 27 | L17: 20260929 | M17: 채택 | O17: NASDAQ 100 Daily Covered Call Target Premium 15% Index | P17: 커버드콜 | Q17: 주식 | R17: 월배당 | S17: 11 | T17: 1 | U17: 0.1656 | V17: 0.0074 | W17: 0.0393 | X17: -0.1155 | Y17: 20250922~20261002 | AA17: =IF(AND($J17<>"",OR(조회_주기="전체",$R17=조회_주기),$J17>=조회_최소,$J17<=조회_최대),1,0) | AB17: =IF($AA17=1,$AB16+1,$AB16) | AC17: =IF(검색어="",1,IF(ISNUMBER(SEARCH(검색어,$A17)),1,0)) | AD17: =IF($AC17=1,$AD16+1,$AD16) | AE17: =IFERROR(INDEX($A$4:$A$594,MATCH(14,$AD$4:$AD$594,0)),"")
A18: TIGER 미국30년국채커버드콜액티브(H) | B18: 476550 | C18: 미래에셋자산운용 | D18: 6380 | E18: 740399000000 | F18: 7686742222 | G18: 0.0039 | H18: 0.0969 | I18: 0.0101 | J18: 0.139812 | K18: 31 | L18: 20260929 | M18: 채택 | O18: KEDI US Treasury 30Y Weekly Covered Call 30 Index | P18: 커버드콜 | Q18: 채권 | R18: 월배당 | S18: 11 | T18: 0 | U18: -0.0911 | V18: -0.2025 | W18: -0.1368 | X18: -0.1077 | Y18: 20250922~20261002 | AA18: =IF(AND($J18<>"",OR(조회_주기="전체",$R18=조회_주기),$J18>=조회_최소,$J18<=조회_최대),1,0) | AB18: =IF($AA18=1,$AB17+1,$AB17) | AC18: =IF(검색어="",1,IF(ISNUMBER(SEARCH(검색어,$A18)),1,0)) | AD18: =IF($AC18=1,$AD17+1,$AD17) | AE18: =IFERROR(INDEX($A$4:$A$594,MATCH(15,$AD$4:$AD$594,0)),"")
A19: SOL 미국30년국채커버드콜(합성) | B19: 473330 | C19: 신한자산운용 | D19: 7400 | E19: 267140000000 | F19: 2121333200 | G19: 0.0025 | H19: 0.1393 | I19: 0.0079 | J19: 0.134054 | K19: 33 | L19: 20260929 | M19: 채택 | O19: KEDI US Treasury 20Y+ 2% OTM BuyWrite Index | P19: 커버드콜 | Q19: 채권 | R19: 월배당 | S19: 11 | T19: 0.749 | U19: -0.0771 | V19: -0.186 | W19: -0.2106 | X19: -0.1981 | Y19: 20250922~20261002 | AA19: =IF(AND($J19<>"",OR(조회_주기="전체",$R19=조회_주기),$J19>=조회_최소,$J19<=조회_최대),1,0) | AB19: =IF($AA19=1,$AB18+1,$AB18) | AC19: =IF(검색어="",1,IF(ISNUMBER(SEARCH(검색어,$A19)),1,0)) | AD19: =IF($AC19=1,$AD18+1,$AD18) | AE19: =IFERROR(INDEX($A$4:$A$594,MATCH(16,$AD$4:$AD$594,0)),"")
A20: KODEX 미국배당다우존스타겟커버드콜 | B20: 483290 | C20: 삼성자산운용(ETF) | D20: 9595 | E20: 170791000000 | F20: 2270734018 | G20: 0.0039 | H20: 0.1582 | I20: 0.01 | J20: 0.130797 | K20: 28 | L20: 20260929 | M20: 채택 | O20: Dow Jones US Dividend 100 10% Premium Covered Call Index(PR) | P20: 커버드콜 | Q20: 주식 | R20: 월배당 | S20: 11 | T20: 0.9267 | U20: 0.2011 | V20: 0.062 | W20: -0.111 | X20: -0.1302 | Y20: 20250922~20261002 | AA20: =IF(AND($J20<>"",OR(조회_주기="전체",$R20=조회_주기),$J20>=조회_최소,$J20<=조회_최대),1,0) | AB20: =IF($AA20=1,$AB19+1,$AB19) | AC20: =IF(검색어="",1,IF(ISNUMBER(SEARCH(검색어,$A20)),1,0)) | AD20: =IF($AC20=1,$AD19+1,$AD19) | AE20: =IFERROR(INDEX($A$4:$A$594,MATCH(17,$AD$4:$AD$594,0)),"")
A21: TIGER 미국나스닥100커버드콜(합성) | B21: 441680 | C21: 미래에셋자산운용 | D21: 10705 | E21: 282076750000 | F21: 839368252 | G21: 0.0037 | H21: 0.1476 | I21: 0.01 | J21: 0.125642 | K21: 48 | L21: 20260929 | M21: 채택 | O21: Cboe NASDAQ-100 BuyWrite V2 Index | P21: 커버드콜 | Q21: 주식 | R21: 월배당 | S21: 11 | T21: 1 | U21: 0.1704 | V21: 0.0396 | W21: -0.0454 | X21: -0.0988 | Y21: 20250922~20261002 | AA21: =IF(AND($J21<>"",OR(조회_주기="전체",$R21=조회_주기),$J21>=조회_최소,$J21<=조회_최대),1,0) | AB21: =IF($AA21=1,$AB20+1,$AB20) | AC21: =IF(검색어="",1,IF(ISNUMBER(SEARCH(검색어,$A21)),1,0)) | AD21: =IF($AC21=1,$AD20+1,$AD20) | AE21: =IFERROR(INDEX($A$4:$A$594,MATCH(18,$AD$4:$AD$594,0)),"")
A22: TIGER 미국S&P500타겟데일리커버드콜 | B22: 482730 | C22: 미래에셋자산운용 | D22: 11440 | E22: 669812000000 | F22: 4581835132 | G22: 0.0025 | H22: 0.1488 | I22: 0.01 | J22: 0.10708 | K22: 28 | L22: 20260914 | M22: 채택 | O22: S&P 500 10% Daily Premium Covered Call Index (USD) PR | P22: 커버드콜 | Q22: 주식 | R22: 월배당 | S22: 11 | T22: 1 | U22: 0.1104 | V22: 0.0027 | W22: -0.0084 | X22: -0.1156 | Y22: 20250922~20261002 | AA22: =IF(AND($J22<>"",OR(조회_주기="전체",$R22=조회_주기),$J22>=조회_최소,$J22<=조회_최대),1,0) | AB22: =IF($AA22=1,$AB21+1,$AB21) | AC22: =IF(검색어="",1,IF(ISNUMBER(SEARCH(검색어,$A22)),1,0)) | AD22: =IF($AC22=1,$AD21+1,$AD21) | AE22: =IFERROR(INDEX($A$4:$A$594,MATCH(19,$AD$4:$AD$594,0)),"")
A23: TIGER 미국배당다우존스타겟커버드콜2호 | B23: 458760 | C23: 미래에셋자산운용 | D23: 10260 | E23: 660231000000 | F23: 3061823728 | G23: 0.0039 | H23: 0.1513 | I23: 0.0086 | J23: 0.10653 | K23: 39 | L23: 20260929 | M23: 채택 | O23: Dow Jones U.S. Dividend 100 7% Premium Covered Call Index | P23: 커버드콜 | Q23: 주식 | R23: 월배당 | S23: 11 | T23: 1 | U23: 0.1975 | V23: 0.0818 | W23: -0.0926 | X23: -0.123 | Y23: 20250922~20261002 | AA23: =IF(AND($J23<>"",OR(조회_주기="전체",$R23=조회_주기),$J23>=조회_최소,$J23<=조회_최대),1,0) | AB23: =IF($AA23=1,$AB22+1,$AB22) | AC23: =IF(검색어="",1,IF(ISNUMBER(SEARCH(검색어,$A23)),1,0)) | AD23: =IF($AC23=1,$AD22+1,$AD22) | AE23: =IFERROR(INDEX($A$4:$A$594,MATCH(20,$AD$4:$AD$594,0)),"")
A24: TIGER 미국테크TOP10타겟커버드콜 | B24: 474220 | C24: 미래에셋자산운용 | D24: 14925 | E24: 420138750000 | F24: 1604795245 | G24: 0.005 | H24: 0.1955 | I24: 0.0083 | J24: 0.105059 | K24: 32 | L24: 20260914 | M24: 채택 | O24: Bloomberg U.S. Tech Top10 + 10% Premium Covered Call Index | P24: 커버드콜 | Q24: 주식 | R24: 월배당 | S24: 11 | T24: 1 | U24: 0.096 | V24: -0.0086 | W24: 0.0018 | X24: -0.0614 | Y24: 20250922~20261002 | AA24: =IF(AND($J24<>"",OR(조회_주기="전체",$R24=조회_주기),$J24>=조회_최소,$J24<=조회_최대),1,0) | AB24: =IF($AA24=1,$AB23+1,$AB23) | AC24: =IF(검색어="",1,IF(ISNUMBER(SEARCH(검색어,$A24)),1,0)) | AD24: =IF($AC24=1,$AD23+1,$AD23) | AE24: =IFERROR(INDEX($A$4:$A$594,MATCH(21,$AD$4:$AD$594,0)),"")
A25: TIGER 리츠부동산인프라 | B25: 329200 | C25: 미래에셋자산운용 | D25: 4045 | E25: 1577145500000 | F25: 11833485434 | G25: 0.0008 | H25: 0.1777 | I25: 0.0081 | J25: 0.097899 | K25: 52 | L25: 20260929 | M25: 채택 | O25: FnGuide 리츠부동산인프라 | P25: 일반 | Q25: 부동산 | R25: 월배당 | S25: 11 | T25: 1 | U25: 0.0207 | V25: -0.07 | W25: -0.1225 | X25: 0.0128 | Y25: 20250922~20261002 | AA25: =IF(AND($J25<>"",OR(조회_주기="전체",$R25=조회_주기),$J25>=조회_최소,$J25<=조회_최대),1,0) | AB25: =IF($AA25=1,$AB24+1,$AB24) | AC25: =IF(검색어="",1,IF(ISNUMBER(SEARCH(검색어,$A25)),1,0)) | AD25: =IF($AC25=1,$AD24+1,$AD24) | AE25: =IFERROR(INDEX($A$4:$A$594,MATCH(22,$AD$4:$AD$594,0)),"")
A26: KODEX 한국부동산리츠인프라 | B26: 476800 | C26: 삼성자산운용(ETF) | D26: 4205 | E26: 488200500000 | F26: 2363556859 | G26: 0.0009 | H26: 0.1488 | I26: 0.0141 | J26: 0.092033 | K26: 30 | L26: 20260914 | M26: 채택 | O26: KRX 부동산리츠인프라 지수 | P26: 일반 | Q26: 부동산 | R26: 월배당 | S26: 11 | T26: 0.9121 | U26: -0.0319 | V26: -0.1134 | W26: -0.1399 | X26: -0.0159 | Y26: 20250922~20261002 | AA26: =IF(AND($J26<>"",OR(조회_주기="전체",$R26=조회_주기),$J26>=조회_최소,$J26<=조회_최대),1,0) | AB26: =IF($AA26=1,$AB25+1,$AB25) | AC26: =IF(검색어="",1,IF(ISNUMBER(SEARCH(검색어,$A26)),1,0)) | AD26: =IF($AC26=1,$AD25+1,$AD25) | AE26: =IFERROR(INDEX($A$4:$A$594,MATCH(23,$AD$4:$AD$594,0)),"")
A27: ACE 글로벌인컴TOP10 | B27: 460960 | C27: 한국투신운용(ETF) | D27: 10395 | E27: 82120500000 | F27: 955805793 | G27: 0.0024 | H27: 0.1134 | I27: 0.0061 | J27: 0.082347 | K27: 38 | L27: 20260929 | M27: 채택 | O27: Solactive Global Superior Income TOP 10 Index PR | P27: 일반 | Q27: 멀티에셋 | R27: 월배당 | S27: 11 | T27: 1 | U27: 0.0012 | V27: -0.0751 | W27: -0.1197 | X27: -0.151 | Y27: 20250922~20261002 | AA27: =IF(AND($J27<>"",OR(조회_주기="전체",$R27=조회_주기),$J27>=조회_최소,$J27<=조회_최대),1,0) | AB27: =IF($AA27=1,$AB26+1,$AB26) | AC27: =IF(검색어="",1,IF(ISNUMBER(SEARCH(검색어,$A27)),1,0)) | AD27: =IF($AC27=1,$AD26+1,$AD26) | AE27: =IFERROR(INDEX($A$4:$A$594,MATCH(24,$AD$4:$AD$594,0)),"")
A28: KODEX iShares미국하이일드액티브 | B28: 468380 | C28: 삼성자산운용(ETF) | D28: 10365 | E28: 87480600000 | F28: 722203366 | G28: 0.0015 | H28: 0.1038 | I28: 0.0057 | J28: 0.074674 | K28: 35 | L28: 20260929 | M28: 채택 | O28: ICE BofAML US HY Constrained Index | P28: 일반 | Q28: 채권 | R28: 월배당 | S28: 11 | T28: 1 | U28: -0.0231 | V28: -0.0911 | W28: -0.1346 | X28: -0.1477 | Y28: 20250922~20261002 | AA28: =IF(AND($J28<>"",OR(조회_주기="전체",$R28=조회_주기),$J28>=조회_최소,$J28<=조회_최대),1,0) | AB28: =IF($AA28=1,$AB27+1,$AB27) | AC28: =IF(검색어="",1,IF(ISNUMBER(SEARCH(검색어,$A28)),1,0)) | AD28: =IF($AC28=1,$AD27+1,$AD27) | AE28: =IFERROR(INDEX($A$4:$A$594,MATCH(25,$AD$4:$AD$594,0)),"")
A29: SOL 코리아고배당 | B29: 0105E0 | C29: 신한자산운용 | D29: 12615 | E29: 524784000000 | F29: 5874730200 | G29: 0.0015 | H29: 0.3016 | I29: 0.0046 | J29: 0.055172 | K29: 11 | L29: 20260914 | M29: 채택 | O29: FnGuide 코리아 고배당 지수 | P29: 일반 | Q29: 주식 | R29: 월배당 | S29: 11 | T29: 0.6078 | U29: 0.3233 | V29: 0.2542 | W29: -0.0022 | X29: -0.0451 | Y29: 20250923~20261002 | AA29: =IF(AND($J29<>"",OR(조회_주기="전체",$R29=조회_주기),$J29>=조회_최소,$J29<=조회_최대),1,0) | AB29: =IF($AA29=1,$AB28+1,$AB28) | AC29: =IF(검색어="",1,IF(ISNUMBER(SEARCH(검색어,$A29)),1,0)) | AD29: =IF($AC29=1,$AD28+1,$AD28) | AE29: =IFERROR(INDEX($A$4:$A$594,MATCH(26,$AD$4:$AD$594,0)),"")
A30: KODEX 미국30년국채액티브(H) | B30: 484790 | C30: 삼성자산운용(ETF) | D30: 7810 | E30: 574581700000 | F30: 4362137267 | G30: 0.00015 | H30: 0.0965 | I30: 0.0044 | J30: 0.05493 | K30: 27 | L30: 20260929 | M30: 채택 | O30: KEDI-KAP 미 국채 20년+ 지수(TR) | P30: 일반 | Q30: 채권 | R30: 월배당 | S30: 11 | T30: 0 | U30: -0.0939 | V30: -0.1411 | W30: -0.1064 | X30: -0.0901 | Y30: 20250922~20261002 | AA30: =IF(AND($J30<>"",OR(조회_주기="전체",$R30=조회_주기),$J30>=조회_최소,$J30<=조회_최대),1,0) | AB30: =IF($AA30=1,$AB29+1,$AB29) | AC30: =IF(검색어="",1,IF(ISNUMBER(SEARCH(검색어,$A30)),1,0)) | AD30: =IF($AC30=1,$AD29+1,$AD29) | AE30: =IFERROR(INDEX($A$4:$A$594,MATCH(27,$AD$4:$AD$594,0)),"")
